Workbook
Name Form_PPS_build: Нормы!$F$19
Name Form_PPS_v_major: Нормы!$F$15
Name Form_PPS_v_minor: Нормы!$F$16
Name ВидыНагр: Нормы!$C$72:$C$74
Name ВидыНагрузки: Нормы!$A$72:$A$74
Name ГруппыВесна: Списки!$P$2:$P$175
Name ГруппыВеснаКол: Списки!$O$177
Name ГруппыОсень: Списки!$H$2:$H$175
Name ГруппыОсеньКол: Списки!$G$177
Name ДисциплиныВесна: Списки!$L$2:$L$175
Name ДисциплиныВеснаКол: Списки!$K$177
Name ДисциплиныОсень: Списки!$D$2:$D$175
Name ДисциплиныОсеньКол: Списки!$C$177
Name ДолжностиППС: Нормы!$A$15:$A$22
Name ДолжностиППС_С: Нормы!$A$15:$A$22
Name ДопОбязанности: Нормы!$A$122:$A$124
Name ЗаданияВесна: весна!$D$5:$F$180
Name ЗаданияОсень: осень!$D$5:$F$180
Name ЗванияППС: Нормы!$C$26:$C$28
Name Институты: Нормы!$A$77:$A$82
Name Кафедры: Нормы!$A$86:$A$119
Name КлючВесна: весна!$C$5:$C$178
Name КлючОсень: осень!$C$5:$C$178
Name ОтраслиНаук: Нормы!$A$31:$A$53
Name Ставка: Нормы!$F$11
Name Ставка_С: Нормы!$F$12
Name СтепениППС: Нормы!$B$23:$B$25
Name Т_Должность: титул!$B$16
Name Т_Должность_С: титул!$F$16
Name Т_Звание: титул!$B$19
Name Т_Институт: титул!$B$8
Name Т_Кафедра: титул!$B$9
Name Т_Преподаватель: титул!$B$15
Name Т_Степень: титул!$B$18
Name Т_УчГод: титул!$B$11
Name Т_Форма: титул!$B$12
Name УровниООП: Нормы!$A$56:$A$62
Name Утв_Весна: титул!$A$40
Name Утв_Осень: титул!$A$39
Name Утв_План: титул!$A$38
Name ФормыООП: Нормы!$A$65:$A$69

Sheet Списки
A1: Осень.Дисциплины | E1: Осень.Группы | I1: Весна.Дисциплины | M1: Весна.Группы | R1: Служебный лист
A2: =TRIM(CLEAN(INDEX(ЗаданияОсень,ROW(A2)-1,1))) | B2: =IF(OR(A2="",COUNTIF(A$2:A2,A2)>1),B3+1,0) | C2: =INDEX(B$2:B$177,B2+1,1)+B2+1 | D2: =INDEX(ЗаданияОсень,C2,1) | E2: =TRIM(CLEAN(INDEX(ЗаданияОсень,ROW(E2)-1,2))) | F2: =IF(OR(E2="",COUNTIF(E$2:E2,E2)>1),F3+1,0) | G2: =INDEX(F$2:F$177,F2+1,1)+F2+1 | H2: =INDEX(ЗаданияОсень,G2,2) | I2: =TRIM(CLEAN(INDEX(ЗаданияВесна,ROW(I2)-1,1))) | J2: =IF(OR(I2="",COUNTIF(I$2:I2,I2)>1),J3+1,0) | K2: =INDEX(J$2:J$177,J2+1,1)+J2+1 | L2: =INDEX(ЗаданияВесна,K2,1) | M2: =TRIM(CLEAN(INDEX(ЗаданияВесна,ROW(M2)-1,2))) | N2: =IF(OR(M2="",COUNTIF(M$2:M2,M2)>1),N3+1,0) | O2: =INDEX(N$2:N$177,N2+1,1)+N2+1 | P2: =INDEX(ЗаданияВесна,O2,2)
A3: =TRIM(CLEAN(INDEX(ЗаданияОсень,ROW(A3)-1,1))) | B3: =IF(OR(A3="",COUNTIF(A$2:A3,A3)>1),B4+1,0) | C3: =INDEX(B$2:B$177,C2+1,1)+C2+1 | D3: =INDEX(ЗаданияОсень,C3,1) | E3: =TRIM(CLEAN(INDEX(ЗаданияОсень,ROW(E3)-1,2))) | F3: =IF(OR(E3="",COUNTIF(E$2:E3,E3)>1),F4+1,0) | G3: =INDEX(F$2:F$177,G2+1,1)+G2+1 | H3: =INDEX(ЗаданияОсень,G3,2) | I3: =TRIM(CLEAN(INDEX(ЗаданияВесна,ROW(I3)-1,1))) | J3: =IF(OR(I3="",COUNTIF(I$2:I3,I3)>1),J4+1,0) | K3: =INDEX(J$2:J$177,K2+1,1)+K2+1 | L3: =INDEX(ЗаданияВесна,K3,1) | M3: =TRIM(CLEAN(INDEX(ЗаданияВесна,ROW(M3)-1,2))) | N3: =IF(OR(M3="",COUNTIF(M$2:M3,M3)>1),N4+1,0) | O3: =INDEX(N$2:N$177,O2+1,1)+O2+1 | P3: =INDEX(ЗаданияВесна,O3,2)
A4: =TRIM(CLEAN(INDEX(ЗаданияОсень,ROW(A4)-1,1))) | B4: =IF(OR(A4="",COUNTIF(A$2:A4,A4)>1),B5+1,0) | C4: =INDEX(B$2:B$177,C3+1,1)+C3+1 | D4: =INDEX(ЗаданияОсень,C4,1) | E4: =TRIM(CLEAN(INDEX(ЗаданияОсень,ROW(E4)-1,2))) | F4: =IF(OR(E4="",COUNTIF(E$2:E4,E4)>1),F5+1,0) | G4: =INDEX(F$2:F$177,G3+1,1)+G3+1 | H4: =INDEX(ЗаданияОсень,G4,2) | I4: =TRIM(CLEAN(INDEX(ЗаданияВесна,ROW(I4)-1,1))) | J4: =IF(OR(I4="",COUNTIF(I$2:I4,I4)>1),J5+1,0) | K4: =INDEX(J$2:J$177,K3+1,1)+K3+1 | L4: =INDEX(ЗаданияВесна,K4,1) | M4: =TRIM(CLEAN(INDEX(ЗаданияВесна,ROW(M4)-1,2))) | N4: =IF(OR(M4="",COUNTIF(M$2:M4,M4)>1),N5+1,0) | O4: =INDEX(N$2:N$177,O3+1,1)+O3+1 | P4: =INDEX(ЗаданияВесна,O4,2)
A5: =TRIM(CLEAN(INDEX(ЗаданияОсень,ROW(A5)-1,1))) | B5: =IF(OR(A5="",COUNTIF(A$2:A5,A5)>1),B6+1,0) | C5: =INDEX(B$2:B$177,C4+1,1)+C4+1 | D5: =INDEX(ЗаданияОсень,C5,1) | E5: =TRIM(CLEAN(INDEX(ЗаданияОсень,ROW(E5)-1,2))) | F5: =IF(OR(E5="",COUNTIF(E$2:E5,E5)>1),F6+1,0) | G5: =INDEX(F$2:F$177,G4+1,1)+G4+1 | H5: =INDEX(ЗаданияОсень,G5,2) | I5: =TRIM(CLEAN(INDEX(ЗаданияВесна,ROW(I5)-1,1))) | J5: =IF(OR(I5="",COUNTIF(I$2:I5,I5)>1),J6+1,0) | K5: =INDEX(J$2:J$177,K4+1,1)+K4+1 | L5: =INDEX(ЗаданияВесна,K5,1) | M5: =TRIM(CLEAN(INDEX(ЗаданияВесна,ROW(M5)-1,2))) | N5: =IF(OR(M5="",COUNTIF(M$2:M5,M5)>1),N6+1,0) | O5: =INDEX(N$2:N$177,O4+1,1)+O4+1 | P5: =INDEX(ЗаданияВесна,O5,2)
A6: =TRIM(CLEAN(INDEX(ЗаданияОсень,ROW(A6)-1,1))) | B6: =IF(OR(A6="",COUNTIF(A$2:A6,A6)>1),B7+1,0) | C6: =INDEX(B$2:B$177,C5+1,1)+C5+1 | D6: =INDEX(ЗаданияОсень,C6,1) | E6: =TRIM(CLEAN(INDEX(ЗаданияОсень,ROW(E6)-1,2))) | F6: =IF(OR(E6="",COUNTIF(E$2:E6,E6)>1),F7+1,0) | G6: =INDEX(F$2:F$177,G5+1,1)+G5+1 | H6: =INDEX(ЗаданияОсень,G6,2) | I6: =TRIM(CLEAN(INDEX(ЗаданияВесна,ROW(I6)-1,1))) | J6: =IF(OR(I6="",COUNTIF(I$2:I6,I6)>1),J7+1,0) | K6: =INDEX(J$2:J$177,K5+1,1)+K5+1 | L6: =INDEX(ЗаданияВесна,K6,1) | M6: =TRIM(CLEAN(INDEX(ЗаданияВесна,ROW(M6)-1,2))) | N6: =IF(OR(M6="",COUNTIF(M$2:M6,M6)>1),N7+1,0) | O6: =INDEX(N$2:N$177,O5+1,1)+O5+1 | P6: =INDEX(ЗаданияВесна,O6,2)
A7: =TRIM(CLEAN(INDEX(ЗаданияОсень,ROW(A7)-1,1))) | B7: =IF(OR(A7="",COUNTIF(A$2:A7,A7)>1),B8+1,0) | C7: =INDEX(B$2:B$177,C6+1,1)+C6+1 | D7: =INDEX(ЗаданияОсень,C7,1) | E7: =TRIM(CLEAN(INDEX(ЗаданияОсень,ROW(E7)-1,2))) | F7: =IF(OR(E7="",COUNTIF(E$2:E7,E7)>1),F8+1,0) | G7: =INDEX(F$2:F$177,G6+1,1)+G6+1 | H7: =INDEX(ЗаданияОсень,G7,2) | I7: =TRIM(CLEAN(INDEX(ЗаданияВесна,ROW(I7)-1,1))) | J7: =IF(OR(I7="",COUNTIF(I$2:I7,I7)>1),J8+1,0) | K7: =INDEX(J$2:J$177,K6+1,1)+K6+1 | L7: =INDEX(ЗаданияВесна,K7,1) | M7: =TRIM(CLEAN(INDEX(ЗаданияВесна,ROW(M7)-1,2))) | N7: =IF(OR(M7="",COUNTIF(M$2:M7,M7)>1),N8+1,0) | O7: =INDEX(N$2:N$177,O6+1,1)+O6+1 | P7: =INDEX(ЗаданияВесна,O7,2)
A8: =TRIM(CLEAN(INDEX(ЗаданияОсень,ROW(A8)-1,1))) | B8: =IF(OR(A8="",COUNTIF(A$2:A8,A8)>1),B9+1,0) | C8: =INDEX(B$2:B$177,C7+1,1)+C7+1 | D8: =INDEX(ЗаданияОсень,C8,1) | E8: =TRIM(CLEAN(INDEX(ЗаданияОсень,ROW(E8)-1,2))) | F8: =IF(OR(E8="",COUNTIF(E$2:E8,E8)>1),F9+1,0) | G8: =INDEX(F$2:F$177,G7+1,1)+G7+1 | H8: =INDEX(ЗаданияОсень,G8,2) | I8: =TRIM(CLEAN(INDEX(ЗаданияВесна,ROW(I8)-1,1))) | J8: =IF(OR(I8="",COUNTIF(I$2:I8,I8)>1),J9+1,0) | K8: =INDEX(J$2:J$177,K7+1,1)+K7+1 | L8: =INDEX(ЗаданияВесна,K8,1) | M8: =TRIM(CLEAN(INDEX(ЗаданияВесна,ROW(M8)-1,2))) | N8: =IF(OR(M8="",COUNTIF(M$2:M8,M8)>1),N9+1,0) | O8: =INDEX(N$2:N$177,O7+1,1)+O7+1 | P8: =INDEX(ЗаданияВесна,O8,2)
A9: =TRIM(CLEAN(INDEX(ЗаданияОсень,ROW(A9)-1,1))) | B9: =IF(OR(A9="",COUNTIF(A$2:A9,A9)>1),B10+1,0) | C9: =INDEX(B$2:B$177,C8+1,1)+C8+1 | D9: =INDEX(ЗаданияОсень,C9,1) | E9: =TRIM(CLEAN(INDEX(ЗаданияОсень,ROW(E9)-1,2))) | F9: =IF(OR(E9="",COUNTIF(E$2:E9,E9)>1),F10+1,0) | G9: =INDEX(F$2:F$177,G8+1,1)+G8+1 | H9: =INDEX(ЗаданияОсень,G9,2) | I9: =TRIM(CLEAN(INDEX(ЗаданияВесна,ROW(I9)-1,1))) | J9: =IF(OR(I9="",COUNTIF(I$2:I9,I9)>1),J10+1,0) | K9: =INDEX(J$2:J$177,K8+1,1)+K8+1 | L9: =INDEX(ЗаданияВесна,K9,1) | M9: =TRIM(CLEAN(INDEX(ЗаданияВесна,ROW(M9)-1,2))) | N9: =IF(OR(M9="",COUNTIF(M$2:M9,M9)>1),N10+1,0) | O9: =INDEX(N$2:N$177,O8+1,1)+O8+1 | P9: =INDEX(ЗаданияВесна,O9,2)
A10: =TRIM(CLEAN(INDEX(ЗаданияОсень,ROW(A10)-1,1))) | B10: =IF(OR(A10="",COUNTIF(A$2:A10,A10)>1),B11+1,0) | C10: =INDEX(B$2:B$177,C9+1,1)+C9+1 | D10: =INDEX(ЗаданияОсень,C10,1) | E10: =TRIM(CLEAN(INDEX(ЗаданияОсень,ROW(E10)-1,2))) | F10: =IF(OR(E10="",COUNTIF(E$2:E10,E10)>1),F11+1,0) | G10: =INDEX(F$2:F$177,G9+1,1)+G9+1 | H10: =INDEX(ЗаданияОсень,G10,2) | I10: =TRIM(CLEAN(INDEX(ЗаданияВесна,ROW(I10)-1,1))) | J10: =IF(OR(I10="",COUNTIF(I$2:I10,I10)>1),J11+1,0) | K10: =INDEX(J$2:J$177,K9+1,1)+K9+1 | L10: =INDEX(ЗаданияВесна,K10,1) | M10: =TRIM(CLEAN(INDEX(ЗаданияВесна,ROW(M10)-1,2))) | N10: =IF(OR(M10="",COUNTIF(M$2:M10,M10)>1),N11+1,0) | O10: =INDEX(N$2:N$177,O9+1,1)+O9+1 | P10: =INDEX(ЗаданияВесна,O10,2)
A11: =TRIM(CLEAN(INDEX(ЗаданияОсень,ROW(A11)-1,1))) | B11: =IF(OR(A11="",COUNTIF(A$2:A11,A11)>1),B12+1,0) | C11: =INDEX(B$2:B$177,C10+1,1)+C10+1 | D11: =INDEX(ЗаданияОсень,C11,1) | E11: =TRIM(CLEAN(INDEX(ЗаданияОсень,ROW(E11)-1,2))) | F11: =IF(OR(E11="",COUNTIF(E$2:E11,E11)>1),F12+1,0) | G11: =INDEX(F$2:F$177,G10+1,1)+G10+1 | H11: =INDEX(ЗаданияОсень,G11,2) | I11: =TRIM(CLEAN(INDEX(ЗаданияВесна,ROW(I11)-1,1))) | J11: =IF(OR(I11="",COUNTIF(I$2:I11,I11)>1),J12+1,0) | K11: =INDEX(J$2:J$177,K10+1,1)+K10+1 | L11: =INDEX(ЗаданияВесна,K11,1) | M11: =TRIM(CLEAN(INDEX(ЗаданияВесна,ROW(M11)-1,2))) | N11: =IF(OR(M11="",COUNTIF(M$2:M11,M11)>1),N12+1,0) | O11: =INDEX(N$2:N$177,O10+1,1)+O10+1 | P11: =INDEX(ЗаданияВесна,O11,2)
A12: =TRIM(CLEAN(INDEX(ЗаданияОсень,ROW(A12)-1,1))) | B12: =IF(OR(A12="",COUNTIF(A$2:A12,A12)>1),B13+1,0) | C12: =INDEX(B$2:B$177,C11+1,1)+C11+1 | D12: =INDEX(ЗаданияОсень,C12,1) | E12: =TRIM(CLEAN(INDEX(ЗаданияОсень,ROW(E12)-1,2))) | F12: =IF(OR(E12="",COUNTIF(E$2:E12,E12)>1),F13+1,0) | G12: =INDEX(F$2:F$177,G11+1,1)+G11+1 | H12: =INDEX(ЗаданияОсень,G12,2) | I12: =TRIM(CLEAN(INDEX(ЗаданияВесна,ROW(I12)-1,1))) | J12: =IF(OR(I12="",COUNTIF(I$2:I12,I12)>1),J13+1,0) | K12: =INDEX(J$2:J$177,K11+1,1)+K11+1 | L12: =INDEX(ЗаданияВесна,K12,1) | M12: =TRIM(CLEAN(INDEX(ЗаданияВесна,ROW(M12)-1,2))) | N12: =IF(OR(M12="",COUNTIF(M$2:M12,M12)>1),N13+1,0) | O12: =INDEX(N$2:N$177,O11+1,1)+O11+1 | P12: =INDEX(ЗаданияВесна,O12,2)
A13: =TRIM(CLEAN(INDEX(ЗаданияОсень,ROW(A13)-1,1))) | B13: =IF(OR(A13="",COUNTIF(A$2:A13,A13)>1),B14+1,0) | C13: =INDEX(B$2:B$177,C12+1,1)+C12+1 | D13: =INDEX(ЗаданияОсень,C13,1) | E13: =TRIM(CLEAN(INDEX(ЗаданияОсень,ROW(E13)-1,2))) | F13: =IF(OR(E13="",COUNTIF(E$2:E13,E13)>1),F14+1,0) | G13: =INDEX(F$2:F$177,G12+1,1)+G12+1 | H13: =INDEX(ЗаданияОсень,G13,2) | I13: =TRIM(CLEAN(INDEX(ЗаданияВесна,ROW(I13)-1,1))) | J13: =IF(OR(I13="",COUNTIF(I$2:I13,I13)>1),J14+1,0) | K13: =INDEX(J$2:J$177,K12+1,1)+K12+1 | L13: =INDEX(ЗаданияВесна,K13,1) | M13: =TRIM(CLEAN(INDEX(ЗаданияВесна,ROW(M13)-1,2))) | N13: =IF(OR(M13="",COUNTIF(M$2:M13,M13)>1),N14+1,0) | O13: =INDEX(N$2:N$177,O12+1,1)+O12+1 | P13: =INDEX(ЗаданияВесна,O13,2)
A14: =TRIM(CLEAN(INDEX(ЗаданияОсень,ROW(A14)-1,1))) | B14: =IF(OR(A14="",COUNTIF(A$2:A14,A14)>1),B15+1,0) | C14: =INDEX(B$2:B$177,C13+1,1)+C13+1 | D14: =INDEX(ЗаданияОсень,C14,1) | E14: =TRIM(CLEAN(INDEX(ЗаданияОсень,ROW(E14)-1,2))) | F14: =IF(OR(E14="",COUNTIF(E$2:E14,E14)>1),F15+1,0) | G14: =INDEX(F$2:F$177,G13+1,1)+G13+1 | H14: =INDEX(ЗаданияОсень,G14,2) | I14: =TRIM(CLEAN(INDEX(ЗаданияВесна,ROW(I14)-1,1))) | J14: =IF(OR(I14="",COUNTIF(I$2:I14,I14)>1),J15+1,0) | K14: =INDEX(J$2:J$177,K13+1,1)+K13+1 | L14: =INDEX(ЗаданияВесна,K14,1) | M14: =TRIM(CLEAN(INDEX(ЗаданияВесна,ROW(M14)-1,2))) | N14: =IF(OR(M14="",COUNTIF(M$2:M14,M14)>1),N15+1,0) | O14: =INDEX(N$2:N$177,O13+1,1)+O13+1 | P14: =INDEX(ЗаданияВесна,O14,2)
... A175: =TRIM(CLEAN(INDEX(ЗаданияОсень,ROW(A175)-1,1))) | B175: =IF(OR(A175="",COUNTIF(A$2:A175,A175)>1),B176+1,0) | C175: =INDEX(B$2:B$177,C174+1,1)+C174+1 | D175: =INDEX(ЗаданияОсень,C175,1) | E175: =TRIM(CLEAN(INDEX(ЗаданияОсень,ROW(E175)-1,2))) | F175: =IF(OR(E175="",COUNTIF(E$2:E175,E175)>1),F176+1,0) | G175: =INDEX(F$2:F$177,G174+1,1)+G174+1 | H175: =INDEX(ЗаданияОсень,G175,2) | I175: =TRIM(CLEAN(INDEX(ЗаданияВесна,ROW(I175)-1,1))) | J175: =IF(OR(I175="",COUNTIF(I$2:I175,I175)>1),J176+1,0) | K175: =INDEX(J$2:J$177,K174+1,1)+K174+1 | L175: =INDEX(ЗаданияВесна,K175,1) | M175: =TRIM(CLEAN(INDEX(ЗаданияВесна,ROW(M175)-1,2))) | N175: =IF(OR(M175="",COUNTIF(M$2:M175,M175)>1),N176+1,0) | O175: =INDEX(N$2:N$177,O174+1,1)+O174+1 | P175: =INDEX(ЗаданияВесна,O175,2)
B177: -1 | C177: =COUNTIF(B2:B175,0) | F177: -1 | G177: =COUNTIF(F2:F175,0) | J177: -1 | K177: =COUNTIF(J2:J175,0) | N177: -1 | O177: =COUNTIF(N2:N175,0)

Sheet Нормы
A1: Должность | B1: Степень | C1: Звание | D1: Код | E1: Норма | F1: Мин | G1: Макс | H1: Пояснение | K1: Служебный лист
D2: =SUMIF(A$15:A$22,A2,D$15:D$22)+SUMIF(B$23:B$25,B2,D$23:D$25)+SUMIF(C$26:C$28,C2,D$26:D$28) | E2: =F2 | F2: 0 | G2: 0 | H2: Никто, такого не бывает
A3: Ассистент | D3: =SUMIF(A$15:A$22,A3,D$15:D$22)+SUMIF(B$23:B$25,B3,D$23:D$25)+SUMIF(C$26:C$28,C3,D$26:D$28) | E3: =F3 | F3: 900 | G3: 900 | H3: введено 2018 г., вне зависимости от звания, степени
A4: Преподаватель | D4: =SUMIF(A$15:A$22,A4,D$15:D$22)+SUMIF(B$23:B$25,B4,D$23:D$25)+SUMIF(C$26:C$28,C4,D$26:D$28) | E4: =F4 | F4: 900 | G4: 900 | H4: введено 2018 г., вне зависимости от звания, степени
A5: Старший преподаватель | D5: =SUMIF(A$15:A$22,A5,D$15:D$22)+SUMIF(B$23:B$25,B5,D$23:D$25)+SUMIF(C$26:C$28,C5,D$26:D$28) | E5: =F5 | F5: 880 | G5: 884 | H5: введено 2018 г., вне зависимости от звания, степени
A6: Доцент | D6: =SUMIF(A$15:A$22,A6,D$15:D$22)+SUMIF(B$23:B$25,B6,D$23:D$25)+SUMIF(C$26:C$28,C6,D$26:D$28) | E6: =F6 | F6: 850 | G6: 854 | H6: введено 2018 г., вне зависимости от звания, степени
A7: Профессор | D7: =SUMIF(A$15:A$22,A7,D$15:D$22)+SUMIF(B$23:B$25,B7,D$23:D$25)+SUMIF(C$26:C$28,C7,D$26:D$28) | E7: =F7 | F7: 800 | G7: 803 | H7: введено 2018 г., вне зависимости от звания, степени
A8: Зав. кафедрой | D8: =SUMIF(A$15:A$22,A8,D$15:D$22)+SUMIF(B$23:B$25,B8,D$23:D$25)+SUMIF(C$26:C$28,C8,D$26:D$28) | E8: =F8 | F8: 450 | G8: 452 | H8: введено 2018 г. (невыпускающей)
A9: Зав. выпускающей кафедрой | D9: =SUMIF(A$15:A$22,A9,D$15:D$22)+SUMIF(B$23:B$25,B9,D$23:D$25)+SUMIF(C$26:C$28,C9,D$26:D$28) | E9: =F9 | F9: 300 | G9: 301 | H9: введено 2018 г.
F10: На ставку
A11: =IF(Т_Должность="","",Т_Должность) | B11: =IF(COUNTIF(Т_Степень,"кандидат*наук")>0,"кандидат наук",IF(COUNTIF(Т_Степень,"доктор*наук")>0,"доктор наук","")) | C11: =IF(Т_Звание="","",Т_Звание) | D11: =SUMIF(A$15:A$22,A11,D$15:D$22)+SUMIF(B$23:B$25,B11,D$23:D$25)+SUMIF(C$26:C$28,C11,D$26:D$28) | E11: =INDEX(E2:E9,MATCH(D11,D2:D9,1)) | F11: =E11 | H11: основное
A12: =IF(Т_Должность_С="","",Т_Должность_С) | B12: =IF(COUNTIF(Т_Степень,"кандидат*наук")>0,"кандидат наук",IF(COUNTIF(Т_Степень,"доктор*наук")>0,"доктор наук","")) | C12: =IF(Т_Звание="","",Т_Звание) | D12: =SUMIF(A$15:A$22,A12,D$15:D$22)+SUMIF(B$23:B$25,B12,D$23:D$25)+SUMIF(C$26:C$28,C12,D$26:D$28) | E12: =INDEX(E2:E9,MATCH(D12,D2:D9,1)) | F12: =E12 | H12: совмещение
A14: Должность | B14: Степень | C14: Звание | D14: Код | F14: версия
A15: зав. выпускающей кафедрой | D15: 700 | F15: 13
A16: зав. кафедрой | D16: 600 | F16: 2
A17: профессор | D17: 500
A18: доцент | D18: 400 | F18: сборка
A19: старший преподаватель | D19: 300 | F19: G
A20: преподаватель | D20: 200
A21: ассистент | D21: 100
A22: (нет) | D22: 0
B23: доктор наук | D23: 20
B24: кандидат наук | D24: 10
B25: (нет) | D25: 0
C26: профессор | D26: 2
C27: доцент | D27: 1
C28: (нет) | D28: 0 | F28: =ЕСЛИ(титул!B17="";"";ЕСЛИ(ЕОШ(НАЙТИ(" ";титул!B17;1));титул!B17;ПСТР(титул!B17;1;НАЙТИ(" ";титул!B17;1)-1)))
A30: Отрасли наук
A31: архитектуры
A32: биологических
A33: ветеринарных
A34: военных
A35: географических
A36: геолого-минералогических
A37: искусствоведения
A38: исторических
A39: культурологии
A40: медицинских
A41: педагогических
... A69: экстернат
...

Sheet Инфо
A1: Краткая инструкция по работе с системой планирования и учета учебной нагрузки преподавателя
A2: Уважаемые коллеги! Данный продукт изначально разрабатывался для личных целей и впоследствии был доработан для использования всеми преподавателями СурГУ, поэтому при разработке не преследовалась цель обеспечения максимальных потребительских качеств, функциональности и надежности, тем более, что Microsoft Excel не обладает для этого достаточными возможностями. Для обеспечения адекватного функционирования системы необходимо соблюдать приведенные ниже правила. Пренебрежение ими может повлечь нарушения вычислений и индикации ошибок при учете фактически выполненной преподавателем работы.
A3: 1 | B3: При открытии данного шаблона тетради, автоматически создается новый документ, который требуется сохранить с новым именем и расширением ".xlsx". В имени файла рекомендуется указать NN - номер кафедры, а также "(заоч)" для тетради по заочной (очно-заочной) форме. Например: "Тетрадь ППС 2021-2022 каф.24 Гришмановский ПВ (заоч).xlsx".
A4: 2 | B4: Первым этапом использования системы является обязательное заполнение листов: - титул - титульный лист, содержащий исходные данные и общие показатели; - осень - план учебной работы на осенний семестр; - весна - план учебной работы на весенний семестр.
A5: 3 | B5: Учет по очной и другим формам обучения, а также учет нагрузки по разным кафедрам, ведется в отдельных электронных тетрадях (в отдельных файлах). Кафедра и форма обучения указываются на титульном листе.
A6: 4 | B6: Учет всех видов нагрузки (по основному месту работы, по совместительству, с почасовой оплатой) по одной кафедре ведется в одной электронной тетради.
A7: 5 | B7: В течение учебного года ежемесячно заполняются листы: - 09, 10, 11, 12, 01 - месяцы осеннего семестра; - 02, 03, 04, 05, 06 - месяцы весеннего семестра; - 07, 08 - для преподавателей, имеющих учебную нагрузку в июле и августе (весенний семестр).
A8: 6 | B8: Лист "карточка" отражает плановую и фактическую нагрузку непосредственно при изменении данных на других листах (ничего считать и вписывать самостоятельно на этом листе не нужно).
A9: 7 | B9: Фактически выполненная работа соотносится с плановой при одновременном совпадении на листах плана ("осень" и "весна") и месяца ("09"-"01" и "02"-"08") совокупности ключевых атрибутов: - Дисциплина, вид учебной работы; - Группа (институт, направление, профиль или специальность, уровень, курс); - Вид нагрузки. Группа может быть указана по ее номеру или в виде шифра, указанного в нагрузке по кафедре, выданной УМУ, но в одной тетради следует строго придерживаться одного варианта.
A10: 8 | B10: Если на листе плана ("осень", "весна") в двух или более строках указаны совпадающие ключевые атрибуты, то они выделяются фоном желтого цвета. Такие строки считаются ошибочными и не учитываются в расчетах.
A11: 9 | B11: Если ключевые атрибуты на листе месяца не совпадают ни с одной записью на листе плана, то они выделяются фоном желтого цвета, а часы, указанные в этой строке - красным. Такие часы считаются ошибочными, подсчитываются отдельно в верхней части листа и не суммируются при подведении итогов.
A12: 10 | B12: Поля "Число месяца", "Подгруппа", "Количество студентов", "Тема занятия" и "Примечания" на листах месяцев введены для повышения информативности и не учитываются в расчетах.
A13: 11 | B13: В случае выполнения работ, изначально не предусмотренных планом, соответствующие данные должны быть внесены на листе плана ("осень", "весна") без указания запланированного объема. После этого могут быть указаны фактические значения выполненной работы на соответствующих листах в зависимости от вида и сроков выпонения работы.
A14: 12 | B14: НЕ ДОПУСКАЕТСЯ использование перетаскивания мышью ячеек на листах - это приведет к нарушению расчетов (особенность MS Excel). Вместо этого следует пользоваться специальными командами копирования (не вырезания!) и вставки (см. п. 13).
... A16: 14 | B16: При печати листов "осень" и "весна", листов по месяцам ("09"-"01" и "02"-"08"), рекомендуется ограничивать количество выводимых страниц, чтобы избежать печати страниц, которые не содержат данных (всего предусмотрено по 4 страницы на план каждого семестра и по 6 страниц на каждый месяц). Для определения количества заполненных страниц можно использовать предварительный просмотр перед печатью.
A18: По всем техническим вопросам (т.е. связанным с функционированием данной системы) следует обращаться к Гришмановскому Павлу Валерьевичу по электронной почте grishmanovskiy_pv@surgu.ru с указанием в теме письма "Тетрадь ППС". (ПРОСТО КЛИКНИТЕ МЫШЬЮ В ЭТОЙ ЯЧЕЙКЕ) В тексте письма необходимо указать характер проблемы и прикрепить к письму файл тетради.

Sheet титул
A2: Бюджетное учреждение высшего образования Ханты-Мансийского автономного округа – Югры «Сургутский государственный университет»
A5: Тетрадь планирования и учёта учебной работы преподавателя
A6: Индивидуальный план и отчет преподавателя
F7: =CONCATENATE("(v. ",Form_PPS_v_major,".",Form_PPS_v_minor,")")
A8: Институт | B8: политехнический
A9: Кафедра | B9: Прикладной математики (1)
A11: Учебный год | B11: 2024/2025
A12: Форма обучения | B12: очная
A15: Преподаватель
A16: Должность | B16: (нет) | D16: Совмещение
A18: Степень | B18: (нет)
A19: Звание | B19: (нет)
A22: Структура учебной нагрузки (в часах):
C23: по плану | D23: по приказу
B24: =INDEX(ВидыНагрузки,1) | C24: =карточка!S71
B25: =INDEX(ВидыНагрузки,2) | C25: =карточка!S72
B26: =INDEX(ВидыНагрузки,3) | C26: =карточка!S73
B27: всего | C27: =карточка!S74 | D27: =SUM(D24:D26)
F29: =COUNTIF(F30:F36,">0")
A44: =CONCATENATE("Сургут, ",MID(B11,1,4)," г.")

Sheet осень
D1: Заполнить | J1: Заполнить только строки "план" (значения в строках "факт" рассчитываются автоматически)
A2: индекс | B2: пусто | C2: ключ | D2: Дисциплина, вид учебной работы | E2: Группа (институт, направление, профиль или специальность, уровень, курс) | F2: Вид нагрузки | G2: План / Факт | H2: Количество подгрупп | I2: Количество студентов | J2: лекции | K2: практические занятия и семинары | L2: лабораторные работы | M2: консультации | N2: контрольные работы | O2: курсовые проекты и работы | P2: зачеты, дифферен-цированные зачеты | Q2: семестровые экзамены | R2: КСР | S2: руководство практиками | T2: руководство научной работой | U2: руководство ВКР (дипломные проекты) | V2: ГЭК, ИАК | W2: прочие | X2: всего | Y2: Отклонение от плана | Z2: Примечания
D3: Всего за семестр | G3: план | J3: =SUMIF($G$5:$G$178,$G3,J$5:J$178) | K3: =SUMIF($G$5:$G$178,$G3,K$5:K$178) | L3: =SUMIF($G$5:$G$178,$G3,L$5:L$178) | M3: =SUMIF($G$5:$G$178,$G3,M$5:M$178) | N3: =SUMIF($G$5:$G$178,$G3,N$5:N$178) | O3: =SUMIF($G$5:$G$178,$G3,O$5:O$178) | P3: =SUMIF($G$5:$G$178,$G3,P$5:P$178) | Q3: =SUMIF($G$5:$G$178,$G3,Q$5:Q$178) | ... W3: =SUMIF($G$5:$G$178,$G3,W$5:W$178) | X3: =SUM(J3:W3) | Y3: =X4-X3 | Z3: =Утв_План
G4: факт | J4: =SUMIF($G$5:$G$178,$G4,J$5:J$178) | K4: =SUMIF($G$5:$G$178,$G4,K$5:K$178) | L4: =SUMIF($G$5:$G$178,$G4,L$5:L$178) | M4: =SUMIF($G$5:$G$178,$G4,M$5:M$178) | N4: =SUMIF($G$5:$G$178,$G4,N$5:N$178) | O4: =SUMIF($G$5:$G$178,$G4,O$5:O$178) | P4: =SUMIF($G$5:$G$178,$G4,P$5:P$178) | Q4: =SUMIF($G$5:$G$178,$G4,Q$5:Q$178) | ... W4: =SUMIF($G$5:$G$178,$G4,W$5:W$178) | X4: =SUM(J4:W4) | Z4: =Утв_Осень
A5: =IF(OR(C5="0",COUNTIF(КлючОсень,C5)>1),0,MATCH(F5,ВидыНагр,0)) | B5: =(COUNTA(D5:F6,J5:W5,H5:I6)=0) | C5: =IF(OR(TRIM(D5)="",COUNTIF(ВидыНагр,F5)<>1),"0",CONCATENATE("$",TRIM(D5),"$",TRIM(E5),"$",F5,"$")) | D5: Дискретная математика | E5: 605-31 (УТС-23-1) | F5: почас. | G5: план | M5: 9 | Q5: 7.2 | X5: =SUM(J5:W5) | Y5: =X6-X5
A6: =-A5 | B6: =B5 | G6: факт | J6: =SUMIF('09'!$D$7:$D$159,$C5,'09'!L$7:L$159)+SUMIF('10'!$D$7:$D$159,$C5,'10'!L$7:L$159)+SUMIF('11'!$D$7:$D$159,$C5,'11'!L$7:L$159)+SUMIF('12'!$D$7:$D$159,$C5,'12'!L$7:L$159)+SUMIF('01'!$D$7:$D$159,$C5,'01'!L$7:L$159) | K6: =SUMIF('09'!$D$7:$D$159,$C5,'09'!M$7:M$159)+SUMIF('10'!$D$7:$D$159,$C5,'10'!M$7:M$159)+SUMIF('11'!$D$7:$D$159,$C5,'11'!M$7:M$159)+SUMIF('12'!$D$7:$D$159,$C5,'12'!M$7:M$159)+SUMIF('01'!$D$7:$D$159,$C5,'01'!M$7:M$159) | L6: =SUMIF('09'!$D$7:$D$159,$C5,'09'!N$7:N$159)+SUMIF('10'!$D$7:$D$159,$C5,'10'!N$7:N$159)+SUMIF('11'!$D$7:$D$159,$C5,'11'!N$7:N$159)+SUMIF('12'!$D$7:$D$159,$C5,'12'!N$7:N$159)+SUMIF('01'!$D$7:$D$159,$C5,'01'!N$7:N$159) | M6: =SUMIF('09'!$D$7:$D$159,$C5,'09'!O$7:O$159)+SUMIF('10'!$D$7:$D$159,$C5,'10'!O$7:O$159)+SUMIF('11'!$D$7:$D$159,$C5,'11'!O$7:O$159)+SUMIF('12'!$D$7:$D$159,$C5,'12'!O$7:O$159)+SUMIF('01'!$D$7:$D$159,$C5,'01'!O$7:O$159) | N6: =SUMIF('09'!$D$7:$D$159,$C5,'09'!P$7:P$159)+SUMIF('10'!$D$7:$D$159,$C5,'10'!P$7:P$159)+SUMIF('11'!$D$7:$D$159,$C5,'11'!P$7:P$159)+SUMIF('12'!$D$7:$D$159,$C5,'12'!P$7:P$159)+SUMIF('01'!$D$7:$D$159,$C5,'01'!P$7:P$159) | O6: =SUMIF('09'!$D$7:$D$159,$C5,'09'!Q$7:Q$159)+SUMIF('10'!$D$7:$D$159,$C5,'10'!Q$7:Q$159)+SUMIF('11'!$D$7:$D$159,$C5,'11'!Q$7:Q$159)+SUMIF('12'!$D$7:$D$159,$C5,'12'!Q$7:Q$159)+SUMIF('01'!$D$7:$D$159,$C5,'01'!Q$7:Q$159) | P6: =SUMIF('09'!$D$7:$D$159,$C5,'09'!R$7:R$159)+SUMIF('10'!$D$7:$D$159,$C5,'10'!R$7:R$159)+SUMIF('11'!$D$7:$D$159,$C5,'11'!R$7:R$159)+SUMIF('12'!$D$7:$D$159,$C5,'12'!R$7:R$159)+SUMIF('01'!$D$7:$D$159,$C5,'01'!R$7:R$159) | Q6: =SUMIF('09'!$D$7:$D$159,$C5,'09'!S$7:S$159)+SUMIF('10'!$D$7:$D$159,$C5,'10'!S$7:S$159)+SUMIF('11'!$D$7:$D$159,$C5,'11'!S$7:S$159)+SUMIF('12'!$D$7:$D$159,$C5,'12'!S$7:S$159)+SUMIF('01'!$D$7:$D$159,$C5,'01'!S$7:S$159) | ... W6: =SUMIF('09'!$D$7:$D$159,$C5,'09'!Y$7:Y$159)+SUMIF('10'!$D$7:$D$159,$C5,'10'!Y$7:Y$159)+SUMIF('11'!$D$7:$D$159,$C5,'11'!Y$7:Y$159)+SUMIF('12'!$D$7:$D$159,$C5,'12'!Y$7:Y$159)+SUMIF('01'!$D$7:$D$159,$C5,'01'!Y$7:Y$159) | X6: =SUM(J6:W6)
A7: =IF(OR(C7="0",COUNTIF(КлючОсень,C7)>1),0,MATCH(F7,ВидыНагр,0)) | B7: =(COUNTA(D7:F8,J7:W7,H7:I8)=0) | C7: =IF(OR(TRIM(D7)="",COUNTIF(ВидыНагр,F7)<>1),"0",CONCATENATE("$",TRIM(D7),"$",TRIM(E7),"$",F7,"$")) | D7: Дискретная математика | E7: 605-31 (УТС-23-1) | F7: совм. | G7: план | K7: 32 | X7: =SUM(J7:W7) | Y7: =X8-X7
A8: =-A7 | B8: =B7 | G8: факт | J8: =SUMIF('09'!$D$7:$D$159,$C7,'09'!L$7:L$159)+SUMIF('10'!$D$7:$D$159,$C7,'10'!L$7:L$159)+SUMIF('11'!$D$7:$D$159,$C7,'11'!L$7:L$159)+SUMIF('12'!$D$7:$D$159,$C7,'12'!L$7:L$159)+SUMIF('01'!$D$7:$D$159,$C7,'01'!L$7:L$159) | K8: =SUMIF('09'!$D$7:$D$159,$C7,'09'!M$7:M$159)+SUMIF('10'!$D$7:$D$159,$C7,'10'!M$7:M$159)+SUMIF('11'!$D$7:$D$159,$C7,'11'!M$7:M$159)+SUMIF('12'!$D$7:$D$159,$C7,'12'!M$7:M$159)+SUMIF('01'!$D$7:$D$159,$C7,'01'!M$7:M$159) | L8: =SUMIF('09'!$D$7:$D$159,$C7,'09'!N$7:N$159)+SUMIF('10'!$D$7:$D$159,$C7,'10'!N$7:N$159)+SUMIF('11'!$D$7:$D$159,$C7,'11'!N$7:N$159)+SUMIF('12'!$D$7:$D$159,$C7,'12'!N$7:N$159)+SUMIF('01'!$D$7:$D$159,$C7,'01'!N$7:N$159) | M8: =SUMIF('09'!$D$7:$D$159,$C7,'09'!O$7:O$159)+SUMIF('10'!$D$7:$D$159,$C7,'10'!O$7:O$159)+SUMIF('11'!$D$7:$D$159,$C7,'11'!O$7:O$159)+SUMIF('12'!$D$7:$D$159,$C7,'12'!O$7:O$159)+SUMIF('01'!$D$7:$D$159,$C7,'01'!O$7:O$159) | N8: =SUMIF('09'!$D$7:$D$159,$C7,'09'!P$7:P$159)+SUMIF('10'!$D$7:$D$159,$C7,'10'!P$7:P$159)+SUMIF('11'!$D$7:$D$159,$C7,'11'!P$7:P$159)+SUMIF('12'!$D$7:$D$159,$C7,'12'!P$7:P$159)+SUMIF('01'!$D$7:$D$159,$C7,'01'!P$7:P$159) | O8: =SUMIF('09'!$D$7:$D$159,$C7,'09'!Q$7:Q$159)+SUMIF('10'!$D$7:$D$159,$C7,'10'!Q$7:Q$159)+SUMIF('11'!$D$7:$D$159,$C7,'11'!Q$7:Q$159)+SUMIF('12'!$D$7:$D$159,$C7,'12'!Q$7:Q$159)+SUMIF('01'!$D$7:$D$159,$C7,'01'!Q$7:Q$159) | P8: =SUMIF('09'!$D$7:$D$159,$C7,'09'!R$7:R$159)+SUMIF('10'!$D$7:$D$159,$C7,'10'!R$7:R$159)+SUMIF('11'!$D$7:$D$159,$C7,'11'!R$7:R$159)+SUMIF('12'!$D$7:$D$159,$C7,'12'!R$7:R$159)+SUMIF('01'!$D$7:$D$159,$C7,'01'!R$7:R$159) | Q8: =SUMIF('09'!$D$7:$D$159,$C7,'09'!S$7:S$159)+SUMIF('10'!$D$7:$D$159,$C7,'10'!S$7:S$159)+SUMIF('11'!$D$7:$D$159,$C7,'11'!S$7:S$159)+SUMIF('12'!$D$7:$D$159,$C7,'12'!S$7:S$159)+SUMIF('01'!$D$7:$D$159,$C7,'01'!S$7:S$159) | ... W8: =SUMIF('09'!$D$7:$D$159,$C7,'09'!Y$7:Y$159)+SUMIF('10'!$D$7:$D$159,$C7,'10'!Y$7:Y$159)+SUMIF('11'!$D$7:$D$159,$C7,'11'!Y$7:Y$159)+SUMIF('12'!$D$7:$D$159,$C7,'12'!Y$7:Y$159)+SUMIF('01'!$D$7:$D$159,$C7,'01'!Y$7:Y$159) | X8: =SUM(J8:W8)
A9: =IF(OR(C9="0",COUNTIF(КлючОсень,C9)>1),0,MATCH(F9,ВидыНагр,0)) | B9: =(COUNTA(D9:F10,J9:W9,H9:I10)=0) | C9: =IF(OR(TRIM(D9)="",COUNTIF(ВидыНагр,F9)<>1),"0",CONCATENATE("$",TRIM(D9),"$",TRIM(E9),"$",F9,"$")) | D9: Математический анализ | E9: 606-42 (ИИиЭС-24-1) | F9: совм. | G9: план | K9: 64 | X9: =SUM(J9:W9) | Y9: =X10-X9
A10: =-A9 | B10: =B9 | G10: факт | J10: =SUMIF('09'!$D$7:$D$159,$C9,'09'!L$7:L$159)+SUMIF('10'!$D$7:$D$159,$C9,'10'!L$7:L$159)+SUMIF('11'!$D$7:$D$159,$C9,'11'!L$7:L$159)+SUMIF('12'!$D$7:$D$159,$C9,'12'!L$7:L$159)+SUMIF('01'!$D$7:$D$159,$C9,'01'!L$7:L$159) | K10: =SUMIF('09'!$D$7:$D$159,$C9,'09'!M$7:M$159)+SUMIF('10'!$D$7:$D$159,$C9,'10'!M$7:M$159)+SUMIF('11'!$D$7:$D$159,$C9,'11'!M$7:M$159)+SUMIF('12'!$D$7:$D$159,$C9,'12'!M$7:M$159)+SUMIF('01'!$D$7:$D$159,$C9,'01'!M$7:M$159) | L10: =SUMIF('09'!$D$7:$D$159,$C9,'09'!N$7:N$159)+SUMIF('10'!$D$7:$D$159,$C9,'10'!N$7:N$159)+SUMIF('11'!$D$7:$D$159,$C9,'11'!N$7:N$159)+SUMIF('12'!$D$7:$D$159,$C9,'12'!N$7:N$159)+SUMIF('01'!$D$7:$D$159,$C9,'01'!N$7:N$159) | M10: =SUMIF('09'!$D$7:$D$159,$C9,'09'!O$7:O$159)+SUMIF('10'!$D$7:$D$159,$C9,'10'!O$7:O$159)+SUMIF('11'!$D$7:$D$159,$C9,'11'!O$7:O$159)+SUMIF('12'!$D$7:$D$159,$C9,'12'!O$7:O$159)+SUMIF('01'!$D$7:$D$159,$C9,'01'!O$7:O$159) | N10: =SUMIF('09'!$D$7:$D$159,$C9,'09'!P$7:P$159)+SUMIF('10'!$D$7:$D$159,$C9,'10'!P$7:P$159)+SUMIF('11'!$D$7:$D$159,$C9,'11'!P$7:P$159)+SUMIF('12'!$D$7:$D$159,$C9,'12'!P$7:P$159)+SUMIF('01'!$D$7:$D$159,$C9,'01'!P$7:P$159) | O10: =SUMIF('09'!$D$7:$D$159,$C9,'09'!Q$7:Q$159)+SUMIF('10'!$D$7:$D$159,$C9,'10'!Q$7:Q$159)+SUMIF('11'!$D$7:$D$159,$C9,'11'!Q$7:Q$159)+SUMIF('12'!$D$7:$D$159,$C9,'12'!Q$7:Q$159)+SUMIF('01'!$D$7:$D$159,$C9,'01'!Q$7:Q$159) | P10: =SUMIF('09'!$D$7:$D$159,$C9,'09'!R$7:R$159)+SUMIF('10'!$D$7:$D$159,$C9,'10'!R$7:R$159)+SUMIF('11'!$D$7:$D$159,$C9,'11'!R$7:R$159)+SUMIF('12'!$D$7:$D$159,$C9,'12'!R$7:R$159)+SUMIF('01'!$D$7:$D$159,$C9,'01'!R$7:R$159) | Q10: =SUMIF('09'!$D$7:$D$159,$C9,'09'!S$7:S$159)+SUMIF('10'!$D$7:$D$159,$C9,'10'!S$7:S$159)+SUMIF('11'!$D$7:$D$159,$C9,'11'!S$7:S$159)+SUMIF('12'!$D$7:$D$159,$C9,'12'!S$7:S$159)+SUMIF('01'!$D$7:$D$159,$C9,'01'!S$7:S$159) | ... W10: =SUMIF('09'!$D$7:$D$159,$C9,'09'!Y$7:Y$159)+SUMIF('10'!$D$7:$D$159,$C9,'10'!Y$7:Y$159)+SUMIF('11'!$D$7:$D$159,$C9,'11'!Y$7:Y$159)+SUMIF('12'!$D$7:$D$159,$C9,'12'!Y$7:Y$159)+SUMIF('01'!$D$7:$D$159,$C9,'01'!Y$7:Y$159) | X10: =SUM(J10:W10)
A11: =IF(OR(C11="0",COUNTIF(КлючОсень,C11)>1),0,MATCH(F11,ВидыНагр,0)) | B11: =(COUNTA(D11:F12,J11:W11,H11:I12)=0) | C11: =IF(OR(TRIM(D11)="",COUNTIF(ВидыНагр,F11)<>1),"0",CONCATENATE("$",TRIM(D11),"$",TRIM(E11),"$",F11,"$")) | D11: Математический анализ | E11: 606-41 (АСОИУ-24-1) | F11: совм. | G11: план | K11: 64 | X11: =SUM(J11:W11) | Y11: =X12-X11
A12: =-A11 | B12: =B11 | G12: факт | J12: =SUMIF('09'!$D$7:$D$159,$C11,'09'!L$7:L$159)+SUMIF('10'!$D$7:$D$159,$C11,'10'!L$7:L$159)+SUMIF('11'!$D$7:$D$159,$C11,'11'!L$7:L$159)+SUMIF('12'!$D$7:$D$159,$C11,'12'!L$7:L$159)+SUMIF('01'!$D$7:$D$159,$C11,'01'!L$7:L$159) | K12: =SUMIF('09'!$D$7:$D$159,$C11,'09'!M$7:M$159)+SUMIF('10'!$D$7:$D$159,$C11,'10'!M$7:M$159)+SUMIF('11'!$D$7:$D$159,$C11,'11'!M$7:M$159)+SUMIF('12'!$D$7:$D$159,$C11,'12'!M$7:M$159)+SUMIF('01'!$D$7:$D$159,$C11,'01'!M$7:M$159) | L12: =SUMIF('09'!$D$7:$D$159,$C11,'09'!N$7:N$159)+SUMIF('10'!$D$7:$D$159,$C11,'10'!N$7:N$159)+SUMIF('11'!$D$7:$D$159,$C11,'11'!N$7:N$159)+SUMIF('12'!$D$7:$D$159,$C11,'12'!N$7:N$159)+SUMIF('01'!$D$7:$D$159,$C11,'01'!N$7:N$159) | M12: =SUMIF('09'!$D$7:$D$159,$C11,'09'!O$7:O$159)+SUMIF('10'!$D$7:$D$159,$C11,'10'!O$7:O$159)+SUMIF('11'!$D$7:$D$159,$C11,'11'!O$7:O$159)+SUMIF('12'!$D$7:$D$159,$C11,'12'!O$7:O$159)+SUMIF('01'!$D$7:$D$159,$C11,'01'!O$7:O$159) | N12: =SUMIF('09'!$D$7:$D$159,$C11,'09'!P$7:P$159)+SUMIF('10'!$D$7:$D$159,$C11,'10'!P$7:P$159)+SUMIF('11'!$D$7:$D$159,$C11,'11'!P$7:P$159)+SUMIF('12'!$D$7:$D$159,$C11,'12'!P$7:P$159)+SUMIF('01'!$D$7:$D$159,$C11,'01'!P$7:P$159) | O12: =SUMIF('09'!$D$7:$D$159,$C11,'09'!Q$7:Q$159)+SUMIF('10'!$D$7:$D$159,$C11,'10'!Q$7:Q$159)+SUMIF('11'!$D$7:$D$159,$C11,'11'!Q$7:Q$159)+SUMIF('12'!$D$7:$D$159,$C11,'12'!Q$7:Q$159)+SUMIF('01'!$D$7:$D$159,$C11,'01'!Q$7:Q$159) | P12: =SUMIF('09'!$D$7:$D$159,$C11,'09'!R$7:R$159)+SUMIF('10'!$D$7:$D$159,$C11,'10'!R$7:R$159)+SUMIF('11'!$D$7:$D$159,$C11,'11'!R$7:R$159)+SUMIF('12'!$D$7:$D$159,$C11,'12'!R$7:R$159)+SUMIF('01'!$D$7:$D$159,$C11,'01'!R$7:R$159) | Q12: =SUMIF('09'!$D$7:$D$159,$C11,'09'!S$7:S$159)+SUMIF('10'!$D$7:$D$159,$C11,'10'!S$7:S$159)+SUMIF('11'!$D$7:$D$159,$C11,'11'!S$7:S$159)+SUMIF('12'!$D$7:$D$159,$C11,'12'!S$7:S$159)+SUMIF('01'!$D$7:$D$159,$C11,'01'!S$7:S$159) | ... W12: =SUMIF('09'!$D$7:$D$159,$C11,'09'!Y$7:Y$159)+SUMIF('10'!$D$7:$D$159,$C11,'10'!Y$7:Y$159)+SUMIF('11'!$D$7:$D$159,$C11,'11'!Y$7:Y$159)+SUMIF('12'!$D$7:$D$159,$C11,'12'!Y$7:Y$159)+SUMIF('01'!$D$7:$D$159,$C11,'01'!Y$7:Y$159) | X12: =SUM(J12:W12)
A13: =IF(OR(C13="0",COUNTIF(КлючОсень,C13)>1),0,MATCH(F13,ВидыНагр,0)) | B13: =(COUNTA(D13:F14,J13:W13,H13:I14)=0) | C13: =IF(OR(TRIM(D13)="",COUNTIF(ВидыНагр,F13)<>1),"0",CONCATENATE("$",TRIM(D13),"$",TRIM(E13),"$",F13,"$")) | D13: Программирование, п/г 3 | E13: 601-41 (ТехнолПрог-24-1) | F13: совм. | G13: план | K13: 64 | X13: =SUM(J13:W13) | Y13: =X14-X13
A14: =-A13 | B14: =B13 | G14: факт | J14: =SUMIF('09'!$D$7:$D$159,$C13,'09'!L$7:L$159)+SUMIF('10'!$D$7:$D$159,$C13,'10'!L$7:L$159)+SUMIF('11'!$D$7:$D$159,$C13,'11'!L$7:L$159)+SUMIF('12'!$D$7:$D$159,$C13,'12'!L$7:L$159)+SUMIF('01'!$D$7:$D$159,$C13,'01'!L$7:L$159) | K14: =SUMIF('09'!$D$7:$D$159,$C13,'09'!M$7:M$159)+SUMIF('10'!$D$7:$D$159,$C13,'10'!M$7:M$159)+SUMIF('11'!$D$7:$D$159,$C13,'11'!M$7:M$159)+SUMIF('12'!$D$7:$D$159,$C13,'12'!M$7:M$159)+SUMIF('01'!$D$7:$D$159,$C13,'01'!M$7:M$159) | L14: =SUMIF('09'!$D$7:$D$159,$C13,'09'!N$7:N$159)+SUMIF('10'!$D$7:$D$159,$C13,'10'!N$7:N$159)+SUMIF('11'!$D$7:$D$159,$C13,'11'!N$7:N$159)+SUMIF('12'!$D$7:$D$159,$C13,'12'!N$7:N$159)+SUMIF('01'!$D$7:$D$159,$C13,'01'!N$7:N$159) | M14: =SUMIF('09'!$D$7:$D$159,$C13,'09'!O$7:O$159)+SUMIF('10'!$D$7:$D$159,$C13,'10'!O$7:O$159)+SUMIF('11'!$D$7:$D$159,$C13,'11'!O$7:O$159)+SUMIF('12'!$D$7:$D$159,$C13,'12'!O$7:O$159)+SUMIF('01'!$D$7:$D$159,$C13,'01'!O$7:O$159) | N14: =SUMIF('09'!$D$7:$D$159,$C13,'09'!P$7:P$159)+SUMIF('10'!$D$7:$D$159,$C13,'10'!P$7:P$159)+SUMIF('11'!$D$7:$D$159,$C13,'11'!P$7:P$159)+SUMIF('12'!$D$7:$D$159,$C13,'12'!P$7:P$159)+SUMIF('01'!$D$7:$D$159,$C13,'01'!P$7:P$159) | O14: =SUMIF('09'!$D$7:$D$159,$C13,'09'!Q$7:Q$159)+SUMIF('10'!$D$7:$D$159,$C13,'10'!Q$7:Q$159)+SUMIF('11'!$D$7:$D$159,$C13,'11'!Q$7:Q$159)+SUMIF('12'!$D$7:$D$159,$C13,'12'!Q$7:Q$159)+SUMIF('01'!$D$7:$D$159,$C13,'01'!Q$7:Q$159) | P14: =SUMIF('09'!$D$7:$D$159,$C13,'09'!R$7:R$159)+SUMIF('10'!$D$7:$D$159,$C13,'10'!R$7:R$159)+SUMIF('11'!$D$7:$D$159,$C13,'11'!R$7:R$159)+SUMIF('12'!$D$7:$D$159,$C13,'12'!R$7:R$159)+SUMIF('01'!$D$7:$D$159,$C13,'01'!R$7:R$159) | Q14: =SUMIF('09'!$D$7:$D$159,$C13,'09'!S$7:S$159)+SUMIF('10'!$D$7:$D$159,$C13,'10'!S$7:S$159)+SUMIF('11'!$D$7:$D$159,$C13,'11'!S$7:S$159)+SUMIF('12'!$D$7:$D$159,$C13,'12'!S$7:S$159)+SUMIF('01'!$D$7:$D$159,$C13,'01'!S$7:S$159) | ... W14: =SUMIF('09'!$D$7:$D$159,$C13,'09'!Y$7:Y$159)+SUMIF('10'!$D$7:$D$159,$C13,'10'!Y$7:Y$159)+SUMIF('11'!$D$7:$D$159,$C13,'11'!Y$7:Y$159)+SUMIF('12'!$D$7:$D$159,$C13,'12'!Y$7:Y$159)+SUMIF('01'!$D$7:$D$159,$C13,'01'!Y$7:Y$159) | X14: =SUM(J14:W14)
A15: =IF(OR(C15="0",COUNTIF(КлючОсень,C15)>1),0,MATCH(F15,ВидыНагр,0)) | B15: =(COUNTA(D15:F16,J15:W15,H15:I16)=0) | C15: =IF(OR(TRIM(D15)="",COUNTIF(ВидыНагр,F15)<>1),"0",CONCATENATE("$",TRIM(D15),"$",TRIM(E15),"$",F15,"$")) | G15: план | X15: =SUM(J15:W15) | Y15: =X16-X15
A16: =-A15 | B16: =B15 | G16: факт | J16: =SUMIF('09'!$D$7:$D$159,$C15,'09'!L$7:L$159)+SUMIF('10'!$D$7:$D$159,$C15,'10'!L$7:L$159)+SUMIF('11'!$D$7:$D$159,$C15,'11'!L$7:L$159)+SUMIF('12'!$D$7:$D$159,$C15,'12'!L$7:L$159)+SUMIF('01'!$D$7:$D$159,$C15,'01'!L$7:L$159) | K16: =SUMIF('09'!$D$7:$D$159,$C15,'09'!M$7:M$159)+SUMIF('10'!$D$7:$D$159,$C15,'10'!M$7:M$159)+SUMIF('11'!$D$7:$D$159,$C15,'11'!M$7:M$159)+SUMIF('12'!$D$7:$D$159,$C15,'12'!M$7:M$159)+SUMIF('01'!$D$7:$D$159,$C15,'01'!M$7:M$159) | L16: =SUMIF('09'!$D$7:$D$159,$C15,'09'!N$7:N$159)+SUMIF('10'!$D$7:$D$159,$C15,'10'!N$7:N$159)+SUMIF('11'!$D$7:$D$159,$C15,'11'!N$7:N$159)+SUMIF('12'!$D$7:$D$159,$C15,'12'!N$7:N$159)+SUMIF('01'!$D$7:$D$159,$C15,'01'!N$7:N$159) | M16: =SUMIF('09'!$D$7:$D$159,$C15,'09'!O$7:O$159)+SUMIF('10'!$D$7:$D$159,$C15,'10'!O$7:O$159)+SUMIF('11'!$D$7:$D$159,$C15,'11'!O$7:O$159)+SUMIF('12'!$D$7:$D$159,$C15,'12'!O$7:O$159)+SUMIF('01'!$D$7:$D$159,$C15,'01'!O$7:O$159) | N16: =SUMIF('09'!$D$7:$D$159,$C15,'09'!P$7:P$159)+SUMIF('10'!$D$7:$D$159,$C15,'10'!P$7:P$159)+SUMIF('11'!$D$7:$D$159,$C15,'11'!P$7:P$159)+SUMIF('12'!$D$7:$D$159,$C15,'12'!P$7:P$159)+SUMIF('01'!$D$7:$D$159,$C15,'01'!P$7:P$159) | O16: =SUMIF('09'!$D$7:$D$159,$C15,'09'!Q$7:Q$159)+SUMIF('10'!$D$7:$D$159,$C15,'10'!Q$7:Q$159)+SUMIF('11'!$D$7:$D$159,$C15,'11'!Q$7:Q$159)+SUMIF('12'!$D$7:$D$159,$C15,'12'!Q$7:Q$159)+SUMIF('01'!$D$7:$D$159,$C15,'01'!Q$7:Q$159) | P16: =SUMIF('09'!$D$7:$D$159,$C15,'09'!R$7:R$159)+SUMIF('10'!$D$7:$D$159,$C15,'10'!R$7:R$159)+SUMIF('11'!$D$7:$D$159,$C15,'11'!R$7:R$159)+SUMIF('12'!$D$7:$D$159,$C15,'12'!R$7:R$159)+SUMIF('01'!$D$7:$D$159,$C15,'01'!R$7:R$159) | Q16: =SUMIF('09'!$D$7:$D$159,$C15,'09'!S$7:S$159)+SUMIF('10'!$D$7:$D$159,$C15,'10'!S$7:S$159)+SUMIF('11'!$D$7:$D$159,$C15,'11'!S$7:S$159)+SUMIF('12'!$D$7:$D$159,$C15,'12'!S$7:S$159)+SUMIF('01'!$D$7:$D$159,$C15,'01'!S$7:S$159) | ... W16: =SUMIF('09'!$D$7:$D$159,$C15,'09'!Y$7:Y$159)+SUMIF('10'!$D$7:$D$159,$C15,'10'!Y$7:Y$159)+SUMIF('11'!$D$7:$D$159,$C15,'11'!Y$7:Y$159)+SUMIF('12'!$D$7:$D$159,$C15,'12'!Y$7:Y$159)+SUMIF('01'!$D$7:$D$159,$C15,'01'!Y$7:Y$159) | X16: =SUM(J16:W16)
A17: =IF(OR(C17="0",COUNTIF(КлючОсень,C17)>1),0,MATCH(F17,ВидыНагр,0)) | B17: =(COUNTA(D17:F18,J17:W17,H17:I18)=0) | C17: =IF(OR(TRIM(D17)="",COUNTIF(ВидыНагр,F17)<>1),"0",CONCATENATE("$",TRIM(D17),"$",TRIM(E17),"$",F17,"$")) | G17: план | X17: =SUM(J17:W17) | Y17: =X18-X17
A18: =-A17 | B18: =B17 | G18: факт | J18: =SUMIF('09'!$D$7:$D$159,$C17,'09'!L$7:L$159)+SUMIF('10'!$D$7:$D$159,$C17,'10'!L$7:L$159)+SUMIF('11'!$D$7:$D$159,$C17,'11'!L$7:L$159)+SUMIF('12'!$D$7:$D$159,$C17,'12'!L$7:L$159)+SUMIF('01'!$D$7:$D$159,$C17,'01'!L$7:L$159) | K18: =SUMIF('09'!$D$7:$D$159,$C17,'09'!M$7:M$159)+SUMIF('10'!$D$7:$D$159,$C17,'10'!M$7:M$159)+SUMIF('11'!$D$7:$D$159,$C17,'11'!M$7:M$159)+SUMIF('12'!$D$7:$D$159,$C17,'12'!M$7:M$159)+SUMIF('01'!$D$7:$D$159,$C17,'01'!M$7:M$159) | L18: =SUMIF('09'!$D$7:$D$159,$C17,'09'!N$7:N$159)+SUMIF('10'!$D$7:$D$159,$C17,'10'!N$7:N$159)+SUMIF('11'!$D$7:$D$159,$C17,'11'!N$7:N$159)+SUMIF('12'!$D$7:$D$159,$C17,'12'!N$7:N$159)+SUMIF('01'!$D$7:$D$159,$C17,'01'!N$7:N$159) | M18: =SUMIF('09'!$D$7:$D$159,$C17,'09'!O$7:O$159)+SUMIF('10'!$D$7:$D$159,$C17,'10'!O$7:O$159)+SUMIF('11'!$D$7:$D$159,$C17,'11'!O$7:O$159)+SUMIF('12'!$D$7:$D$159,$C17,'12'!O$7:O$159)+SUMIF('01'!$D$7:$D$159,$C17,'01'!O$7:O$159) | N18: =SUMIF('09'!$D$7:$D$159,$C17,'09'!P$7:P$159)+SUMIF('10'!$D$7:$D$159,$C17,'10'!P$7:P$159)+SUMIF('11'!$D$7:$D$159,$C17,'11'!P$7:P$159)+SUMIF('12'!$D$7:$D$159,$C17,'12'!P$7:P$159)+SUMIF('01'!$D$7:$D$159,$C17,'01'!P$7:P$159) | O18: =SUMIF('09'!$D$7:$D$159,$C17,'09'!Q$7:Q$159)+SUMIF('10'!$D$7:$D$159,$C17,'10'!Q$7:Q$159)+SUMIF('11'!$D$7:$D$159,$C17,'11'!Q$7:Q$159)+SUMIF('12'!$D$7:$D$159,$C17,'12'!Q$7:Q$159)+SUMIF('01'!$D$7:$D$159,$C17,'01'!Q$7:Q$159) | P18: =SUMIF('09'!$D$7:$D$159,$C17,'09'!R$7:R$159)+SUMIF('10'!$D$7:$D$159,$C17,'10'!R$7:R$159)+SUMIF('11'!$D$7:$D$159,$C17,'11'!R$7:R$159)+SUMIF('12'!$D$7:$D$159,$C17,'12'!R$7:R$159)+SUMIF('01'!$D$7:$D$159,$C17,'01'!R$7:R$159) | Q18: =SUMIF('09'!$D$7:$D$159,$C17,'09'!S$7:S$159)+SUMIF('10'!$D$7:$D$159,$C17,'10'!S$7:S$159)+SUMIF('11'!$D$7:$D$159,$C17,'11'!S$7:S$159)+SUMIF('12'!$D$7:$D$159,$C17,'12'!S$7:S$159)+SUMIF('01'!$D$7:$D$159,$C17,'01'!S$7:S$159) | ... W18: =SUMIF('09'!$D$7:$D$159,$C17,'09'!Y$7:Y$159)+SUMIF('10'!$D$7:$D$159,$C17,'10'!Y$7:Y$159)+SUMIF('11'!$D$7:$D$159,$C17,'11'!Y$7:Y$159)+SUMIF('12'!$D$7:$D$159,$C17,'12'!Y$7:Y$159)+SUMIF('01'!$D$7:$D$159,$C17,'01'!Y$7:Y$159) | X18: =SUM(J18:W18)
A19: =IF(OR(C19="0",COUNTIF(КлючОсень,C19)>1),0,MATCH(F19,ВидыНагр,0)) | B19: =(COUNTA(D19:F20,J19:W19,H19:I20)=0) | C19: =IF(OR(TRIM(D19)="",COUNTIF(ВидыНагр,F19)<>1),"0",CONCATENATE("$",TRIM(D19),"$",TRIM(E19),"$",F19,"$")) | G19: план | X19: =SUM(J19:W19) | Y19: =X20-X19
A20: =-A19 | B20: =B19 | G20: факт | J20: =SUMIF('09'!$D$7:$D$159,$C19,'09'!L$7:L$159)+SUMIF('10'!$D$7:$D$159,$C19,'10'!L$7:L$159)+SUMIF('11'!$D$7:$D$159,$C19,'11'!L$7:L$159)+SUMIF('12'!$D$7:$D$159,$C19,'12'!L$7:L$159)+SUMIF('01'!$D$7:$D$159,$C19,'01'!L$7:L$159) | K20: =SUMIF('09'!$D$7:$D$159,$C19,'09'!M$7:M$159)+SUMIF('10'!$D$7:$D$159,$C19,'10'!M$7:M$159)+SUMIF('11'!$D$7:$D$159,$C19,'11'!M$7:M$159)+SUMIF('12'!$D$7:$D$159,$C19,'12'!M$7:M$159)+SUMIF('01'!$D$7:$D$159,$C19,'01'!M$7:M$159) | L20: =SUMIF('09'!$D$7:$D$159,$C19,'09'!N$7:N$159)+SUMIF('10'!$D$7:$D$159,$C19,'10'!N$7:N$159)+SUMIF('11'!$D$7:$D$159,$C19,'11'!N$7:N$159)+SUMIF('12'!$D$7:$D$159,$C19,'12'!N$7:N$159)+SUMIF('01'!$D$7:$D$159,$C19,'01'!N$7:N$159) | M20: =SUMIF('09'!$D$7:$D$159,$C19,'09'!O$7:O$159)+SUMIF('10'!$D$7:$D$159,$C19,'10'!O$7:O$159)+SUMIF('11'!$D$7:$D$159,$C19,'11'!O$7:O$159)+SUMIF('12'!$D$7:$D$159,$C19,'12'!O$7:O$159)+SUMIF('01'!$D$7:$D$159,$C19,'01'!O$7:O$159) | N20: =SUMIF('09'!$D$7:$D$159,$C19,'09'!P$7:P$159)+SUMIF('10'!$D$7:$D$159,$C19,'10'!P$7:P$159)+SUMIF('11'!$D$7:$D$159,$C19,'11'!P$7:P$159)+SUMIF('12'!$D$7:$D$159,$C19,'12'!P$7:P$159)+SUMIF('01'!$D$7:$D$159,$C19,'01'!P$7:P$159) | O20: =SUMIF('09'!$D$7:$D$159,$C19,'09'!Q$7:Q$159)+SUMIF('10'!$D$7:$D$159,$C19,'10'!Q$7:Q$159)+SUMIF('11'!$D$7:$D$159,$C19,'11'!Q$7:Q$159)+SUMIF('12'!$D$7:$D$159,$C19,'12'!Q$7:Q$159)+SUMIF('01'!$D$7:$D$159,$C19,'01'!Q$7:Q$159) | P20: =SUMIF('09'!$D$7:$D$159,$C19,'09'!R$7:R$159)+SUMIF('10'!$D$7:$D$159,$C19,'10'!R$7:R$159)+SUMIF('11'!$D$7:$D$159,$C19,'11'!R$7:R$159)+SUMIF('12'!$D$7:$D$159,$C19,'12'!R$7:R$159)+SUMIF('01'!$D$7:$D$159,$C19,'01'!R$7:R$159) | Q20: =SUMIF('09'!$D$7:$D$159,$C19,'09'!S$7:S$159)+SUMIF('10'!$D$7:$D$159,$C19,'10'!S$7:S$159)+SUMIF('11'!$D$7:$D$159,$C19,'11'!S$7:S$159)+SUMIF('12'!$D$7:$D$159,$C19,'12'!S$7:S$159)+SUMIF('01'!$D$7:$D$159,$C19,'01'!S$7:S$159) | ... W20: =SUMIF('09'!$D$7:$D$159,$C19,'09'!Y$7:Y$159)+SUMIF('10'!$D$7:$D$159,$C19,'10'!Y$7:Y$159)+SUMIF('11'!$D$7:$D$159,$C19,'11'!Y$7:Y$159)+SUMIF('12'!$D$7:$D$159,$C19,'12'!Y$7:Y$159)+SUMIF('01'!$D$7:$D$159,$C19,'01'!Y$7:Y$159) | X20: =SUM(J20:W20)
A21: =IF(OR(C21="0",COUNTIF(КлючОсень,C21)>1),0,MATCH(F21,ВидыНагр,0)) | B21: =(COUNTA(D21:F22,J21:W21,H21:I22)=0) | C21: =IF(OR(TRIM(D21)="",COUNTIF(ВидыНагр,F21)<>1),"0",CONCATENATE("$",TRIM(D21),"$",TRIM(E21),"$",F21,"$")) | G21: план | X21: =SUM(J21:W21) | Y21: =X22-X21
A22: =-A21 | B22: =B21 | G22: факт | J22: =SUMIF('09'!$D$7:$D$159,$C21,'09'!L$7:L$159)+SUMIF('10'!$D$7:$D$159,$C21,'10'!L$7:L$159)+SUMIF('11'!$D$7:$D$159,$C21,'11'!L$7:L$159)+SUMIF('12'!$D$7:$D$159,$C21,'12'!L$7:L$159)+SUMIF('01'!$D$7:$D$159,$C21,'01'!L$7:L$159) | K22: =SUMIF('09'!$D$7:$D$159,$C21,'09'!M$7:M$159)+SUMIF('10'!$D$7:$D$159,$C21,'10'!M$7:M$159)+SUMIF('11'!$D$7:$D$159,$C21,'11'!M$7:M$159)+SUMIF('12'!$D$7:$D$159,$C21,'12'!M$7:M$159)+SUMIF('01'!$D$7:$D$159,$C21,'01'!M$7:M$159) | L22: =SUMIF('09'!$D$7:$D$159,$C21,'09'!N$7:N$159)+SUMIF('10'!$D$7:$D$159,$C21,'10'!N$7:N$159)+SUMIF('11'!$D$7:$D$159,$C21,'11'!N$7:N$159)+SUMIF('12'!$D$7:$D$159,$C21,'12'!N$7:N$159)+SUMIF('01'!$D$7:$D$159,$C21,'01'!N$7:N$159) | M22: =SUMIF('09'!$D$7:$D$159,$C21,'09'!O$7:O$159)+SUMIF('10'!$D$7:$D$159,$C21,'10'!O$7:O$159)+SUMIF('11'!$D$7:$D$159,$C21,'11'!O$7:O$159)+SUMIF('12'!$D$7:$D$159,$C21,'12'!O$7:O$159)+SUMIF('01'!$D$7:$D$159,$C21,'01'!O$7:O$159) | N22: =SUMIF('09'!$D$7:$D$159,$C21,'09'!P$7:P$159)+SUMIF('10'!$D$7:$D$159,$C21,'10'!P$7:P$159)+SUMIF('11'!$D$7:$D$159,$C21,'11'!P$7:P$159)+SUMIF('12'!$D$7:$D$159,$C21,'12'!P$7:P$159)+SUMIF('01'!$D$7:$D$159,$C21,'01'!P$7:P$159) | O22: =SUMIF('09'!$D$7:$D$159,$C21,'09'!Q$7:Q$159)+SUMIF('10'!$D$7:$D$159,$C21,'10'!Q$7:Q$159)+SUMIF('11'!$D$7:$D$159,$C21,'11'!Q$7:Q$159)+SUMIF('12'!$D$7:$D$159,$C21,'12'!Q$7:Q$159)+SUMIF('01'!$D$7:$D$159,$C21,'01'!Q$7:Q$159) | P22: =SUMIF('09'!$D$7:$D$159,$C21,'09'!R$7:R$159)+SUMIF('10'!$D$7:$D$159,$C21,'10'!R$7:R$159)+SUMIF('11'!$D$7:$D$159,$C21,'11'!R$7:R$159)+SUMIF('12'!$D$7:$D$159,$C21,'12'!R$7:R$159)+SUMIF('01'!$D$7:$D$159,$C21,'01'!R$7:R$159) | Q22: =SUMIF('09'!$D$7:$D$159,$C21,'09'!S$7:S$159)+SUMIF('10'!$D$7:$D$159,$C21,'10'!S$7:S$159)+SUMIF('11'!$D$7:$D$159,$C21,'11'!S$7:S$159)+SUMIF('12'!$D$7:$D$159,$C21,'12'!S$7:S$159)+SUMIF('01'!$D$7:$D$159,$C21,'01'!S$7:S$159) | ... W22: =SUMIF('09'!$D$7:$D$159,$C21,'09'!Y$7:Y$159)+SUMIF('10'!$D$7:$D$159,$C21,'10'!Y$7:Y$159)+SUMIF('11'!$D$7:$D$159,$C21,'11'!Y$7:Y$159)+SUMIF('12'!$D$7:$D$159,$C21,'12'!Y$7:Y$159)+SUMIF('01'!$D$7:$D$159,$C21,'01'!Y$7:Y$159) | X22: =SUM(J22:W22)
A23: =IF(OR(C23="0",COUNTIF(КлючОсень,C23)>1),0,MATCH(F23,ВидыНагр,0)) | B23: =(COUNTA(D23:F24,J23:W23,H23:I24)=0) | C23: =IF(OR(TRIM(D23)="",COUNTIF(ВидыНагр,F23)<>1),"0",CONCATENATE("$",TRIM(D23),"$",TRIM(E23),"$",F23,"$")) | G23: план | X23: =SUM(J23:W23) | Y23: =X24-X23
A24: =-A23 | B24: =B23 | G24: факт | J24: =SUMIF('09'!$D$7:$D$159,$C23,'09'!L$7:L$159)+SUMIF('10'!$D$7:$D$159,$C23,'10'!L$7:L$159)+SUMIF('11'!$D$7:$D$159,$C23,'11'!L$7:L$159)+SUMIF('12'!$D$7:$D$159,$C23,'12'!L$7:L$159)+SUMIF('01'!$D$7:$D$159,$C23,'01'!L$7:L$159) | K24: =SUMIF('09'!$D$7:$D$159,$C23,'09'!M$7:M$159)+SUMIF('10'!$D$7:$D$159,$C23,'10'!M$7:M$159)+SUMIF('11'!$D$7:$D$159,$C23,'11'!M$7:M$159)+SUMIF('12'!$D$7:$D$159,$C23,'12'!M$7:M$159)+SUMIF('01'!$D$7:$D$159,$C23,'01'!M$7:M$159) | L24: =SUMIF('09'!$D$7:$D$159,$C23,'09'!N$7:N$159)+SUMIF('10'!$D$7:$D$159,$C23,'10'!N$7:N$159)+SUMIF('11'!$D$7:$D$159,$C23,'11'!N$7:N$159)+SUMIF('12'!$D$7:$D$159,$C23,'12'!N$7:N$159)+SUMIF('01'!$D$7:$D$159,$C23,'01'!N$7:N$159) | M24: =SUMIF('09'!$D$7:$D$159,$C23,'09'!O$7:O$159)+SUMIF('10'!$D$7:$D$159,$C23,'10'!O$7:O$159)+SUMIF('11'!$D$7:$D$159,$C23,'11'!O$7:O$159)+SUMIF('12'!$D$7:$D$159,$C23,'12'!O$7:O$159)+SUMIF('01'!$D$7:$D$159,$C23,'01'!O$7:O$159) | N24: =SUMIF('09'!$D$7:$D$159,$C23,'09'!P$7:P$159)+SUMIF('10'!$D$7:$D$159,$C23,'10'!P$7:P$159)+SUMIF('11'!$D$7:$D$159,$C23,'11'!P$7:P$159)+SUMIF('12'!$D$7:$D$159,$C23,'12'!P$7:P$159)+SUMIF('01'!$D$7:$D$159,$C23,'01'!P$7:P$159) | O24: =SUMIF('09'!$D$7:$D$159,$C23,'09'!Q$7:Q$159)+SUMIF('10'!$D$7:$D$159,$C23,'10'!Q$7:Q$159)+SUMIF('11'!$D$7:$D$159,$C23,'11'!Q$7:Q$159)+SUMIF('12'!$D$7:$D$159,$C23,'12'!Q$7:Q$159)+SUMIF('01'!$D$7:$D$159,$C23,'01'!Q$7:Q$159) | P24: =SUMIF('09'!$D$7:$D$159,$C23,'09'!R$7:R$159)+SUMIF('10'!$D$7:$D$159,$C23,'10'!R$7:R$159)+SUMIF('11'!$D$7:$D$159,$C23,'11'!R$7:R$159)+SUMIF('12'!$D$7:$D$159,$C23,'12'!R$7:R$159)+SUMIF('01'!$D$7:$D$159,$C23,'01'!R$7:R$159) | Q24: =SUMIF('09'!$D$7:$D$159,$C23,'09'!S$7:S$159)+SUMIF('10'!$D$7:$D$159,$C23,'10'!S$7:S$159)+SUMIF('11'!$D$7:$D$159,$C23,'11'!S$7:S$159)+SUMIF('12'!$D$7:$D$159,$C23,'12'!S$7:S$159)+SUMIF('01'!$D$7:$D$159,$C23,'01'!S$7:S$159) | ... W24: =SUMIF('09'!$D$7:$D$159,$C23,'09'!Y$7:Y$159)+SUMIF('10'!$D$7:$D$159,$C23,'10'!Y$7:Y$159)+SUMIF('11'!$D$7:$D$159,$C23,'11'!Y$7:Y$159)+SUMIF('12'!$D$7:$D$159,$C23,'12'!Y$7:Y$159)+SUMIF('01'!$D$7:$D$159,$C23,'01'!Y$7:Y$159) | X24: =SUM(J24:W24)
A25: =IF(OR(C25="0",COUNTIF(КлючОсень,C25)>1),0,MATCH(F25,ВидыНагр,0)) | B25: =(COUNTA(D25:F26,J25:W25,H25:I26)=0) | C25: =IF(OR(TRIM(D25)="",COUNTIF(ВидыНагр,F25)<>1),"0",CONCATENATE("$",TRIM(D25),"$",TRIM(E25),"$",F25,"$")) | G25: план | X25: =SUM(J25:W25) | Y25: =X26-X25
A26: =-A25 | B26: =B25 | G26: факт | J26: =SUMIF('09'!$D$7:$D$159,$C25,'09'!L$7:L$159)+SUMIF('10'!$D$7:$D$159,$C25,'10'!L$7:L$159)+SUMIF('11'!$D$7:$D$159,$C25,'11'!L$7:L$159)+SUMIF('12'!$D$7:$D$159,$C25,'12'!L$7:L$159)+SUMIF('01'!$D$7:$D$159,$C25,'01'!L$7:L$159) | K26: =SUMIF('09'!$D$7:$D$159,$C25,'09'!M$7:M$159)+SUMIF('10'!$D$7:$D$159,$C25,'10'!M$7:M$159)+SUMIF('11'!$D$7:$D$159,$C25,'11'!M$7:M$159)+SUMIF('12'!$D$7:$D$159,$C25,'12'!M$7:M$159)+SUMIF('01'!$D$7:$D$159,$C25,'01'!M$7:M$159) | L26: =SUMIF('09'!$D$7:$D$159,$C25,'09'!N$7:N$159)+SUMIF('10'!$D$7:$D$159,$C25,'10'!N$7:N$159)+SUMIF('11'!$D$7:$D$159,$C25,'11'!N$7:N$159)+SUMIF('12'!$D$7:$D$159,$C25,'12'!N$7:N$159)+SUMIF('01'!$D$7:$D$159,$C25,'01'!N$7:N$159) | M26: =SUMIF('09'!$D$7:$D$159,$C25,'09'!O$7:O$159)+SUMIF('10'!$D$7:$D$159,$C25,'10'!O$7:O$159)+SUMIF('11'!$D$7:$D$159,$C25,'11'!O$7:O$159)+SUMIF('12'!$D$7:$D$159,$C25,'12'!O$7:O$159)+SUMIF('01'!$D$7:$D$159,$C25,'01'!O$7:O$159) | N26: =SUMIF('09'!$D$7:$D$159,$C25,'09'!P$7:P$159)+SUMIF('10'!$D$7:$D$159,$C25,'10'!P$7:P$159)+SUMIF('11'!$D$7:$D$159,$C25,'11'!P$7:P$159)+SUMIF('12'!$D$7:$D$159,$C25,'12'!P$7:P$159)+SUMIF('01'!$D$7:$D$159,$C25,'01'!P$7:P$159) | O26: =SUMIF('09'!$D$7:$D$159,$C25,'09'!Q$7:Q$159)+SUMIF('10'!$D$7:$D$159,$C25,'10'!Q$7:Q$159)+SUMIF('11'!$D$7:$D$159,$C25,'11'!Q$7:Q$159)+SUMIF('12'!$D$7:$D$159,$C25,'12'!Q$7:Q$159)+SUMIF('01'!$D$7:$D$159,$C25,'01'!Q$7:Q$159) | P26: =SUMIF('09'!$D$7:$D$159,$C25,'09'!R$7:R$159)+SUMIF('10'!$D$7:$D$159,$C25,'10'!R$7:R$159)+SUMIF('11'!$D$7:$D$159,$C25,'11'!R$7:R$159)+SUMIF('12'!$D$7:$D$159,$C25,'12'!R$7:R$159)+SUMIF('01'!$D$7:$D$159,$C25,'01'!R$7:R$159) | Q26: =SUMIF('09'!$D$7:$D$159,$C25,'09'!S$7:S$159)+SUMIF('10'!$D$7:$D$159,$C25,'10'!S$7:S$159)+SUMIF('11'!$D$7:$D$159,$C25,'11'!S$7:S$159)+SUMIF('12'!$D$7:$D$159,$C25,'12'!S$7:S$159)+SUMIF('01'!$D$7:$D$159,$C25,'01'!S$7:S$159) | ... W26: =SUMIF('09'!$D$7:$D$159,$C25,'09'!Y$7:Y$159)+SUMIF('10'!$D$7:$D$159,$C25,'10'!Y$7:Y$159)+SUMIF('11'!$D$7:$D$159,$C25,'11'!Y$7:Y$159)+SUMIF('12'!$D$7:$D$159,$C25,'12'!Y$7:Y$159)+SUMIF('01'!$D$7:$D$159,$C25,'01'!Y$7:Y$159) | X26: =SUM(J26:W26)
A27: =IF(OR(C27="0",COUNTIF(КлючОсень,C27)>1),0,MATCH(F27,ВидыНагр,0)) | B27: =(COUNTA(D27:F28,J27:W27,H27:I28)=0) | C27: =IF(OR(TRIM(D27)="",COUNTIF(ВидыНагр,F27)<>1),"0",CONCATENATE("$",TRIM(D27),"$",TRIM(E27),"$",F27,"$")) | G27: план | X27: =SUM(J27:W27) | Y27: =X28-X27
A28: =-A27 | B28: =B27 | G28: факт | J28: =SUMIF('09'!$D$7:$D$159,$C27,'09'!L$7:L$159)+SUMIF('10'!$D$7:$D$159,$C27,'10'!L$7:L$159)+SUMIF('11'!$D$7:$D$159,$C27,'11'!L$7:L$159)+SUMIF('12'!$D$7:$D$159,$C27,'12'!L$7:L$159)+SUMIF('01'!$D$7:$D$159,$C27,'01'!L$7:L$159) | K28: =SUMIF('09'!$D$7:$D$159,$C27,'09'!M$7:M$159)+SUMIF('10'!$D$7:$D$159,$C27,'10'!M$7:M$159)+SUMIF('11'!$D$7:$D$159,$C27,'11'!M$7:M$159)+SUMIF('12'!$D$7:$D$159,$C27,'12'!M$7:M$159)+SUMIF('01'!$D$7:$D$159,$C27,'01'!M$7:M$159) | L28: =SUMIF('09'!$D$7:$D$159,$C27,'09'!N$7:N$159)+SUMIF('10'!$D$7:$D$159,$C27,'10'!N$7:N$159)+SUMIF('11'!$D$7:$D$159,$C27,'11'!N$7:N$159)+SUMIF('12'!$D$7:$D$159,$C27,'12'!N$7:N$159)+SUMIF('01'!$D$7:$D$159,$C27,'01'!N$7:N$159) | M28: =SUMIF('09'!$D$7:$D$159,$C27,'09'!O$7:O$159)+SUMIF('10'!$D$7:$D$159,$C27,'10'!O$7:O$159)+SUMIF('11'!$D$7:$D$159,$C27,'11'!O$7:O$159)+SUMIF('12'!$D$7:$D$159,$C27,'12'!O$7:O$159)+SUMIF('01'!$D$7:$D$159,$C27,'01'!O$7:O$159) | N28: =SUMIF('09'!$D$7:$D$159,$C27,'09'!P$7:P$159)+SUMIF('10'!$D$7:$D$159,$C27,'10'!P$7:P$159)+SUMIF('11'!$D$7:$D$159,$C27,'11'!P$7:P$159)+SUMIF('12'!$D$7:$D$159,$C27,'12'!P$7:P$159)+SUMIF('01'!$D$7:$D$159,$C27,'01'!P$7:P$159) | O28: =SUMIF('09'!$D$7:$D$159,$C27,'09'!Q$7:Q$159)+SUMIF('10'!$D$7:$D$159,$C27,'10'!Q$7:Q$159)+SUMIF('11'!$D$7:$D$159,$C27,'11'!Q$7:Q$159)+SUMIF('12'!$D$7:$D$159,$C27,'12'!Q$7:Q$159)+SUMIF('01'!$D$7:$D$159,$C27,'01'!Q$7:Q$159) | P28: =SUMIF('09'!$D$7:$D$159,$C27,'09'!R$7:R$159)+SUMIF('10'!$D$7:$D$159,$C27,'10'!R$7:R$159)+SUMIF('11'!$D$7:$D$159,$C27,'11'!R$7:R$159)+SUMIF('12'!$D$7:$D$159,$C27,'12'!R$7:R$159)+SUMIF('01'!$D$7:$D$159,$C27,'01'!R$7:R$159) | Q28: =SUMIF('09'!$D$7:$D$159,$C27,'09'!S$7:S$159)+SUMIF('10'!$D$7:$D$159,$C27,'10'!S$7:S$159)+SUMIF('11'!$D$7:$D$159,$C27,'11'!S$7:S$159)+SUMIF('12'!$D$7:$D$159,$C27,'12'!S$7:S$159)+SUMIF('01'!$D$7:$D$159,$C27,'01'!S$7:S$159) | ... W28: =SUMIF('09'!$D$7:$D$159,$C27,'09'!Y$7:Y$159)+SUMIF('10'!$D$7:$D$159,$C27,'10'!Y$7:Y$159)+SUMIF('11'!$D$7:$D$159,$C27,'11'!Y$7:Y$159)+SUMIF('12'!$D$7:$D$159,$C27,'12'!Y$7:Y$159)+SUMIF('01'!$D$7:$D$159,$C27,'01'!Y$7:Y$159) | X28: =SUM(J28:W28)
A29: =IF(OR(C29="0",COUNTIF(КлючОсень,C29)>1),0,MATCH(F29,ВидыНагр,0)) | B29: =(COUNTA(D29:F30,J29:W29,H29:I30)=0) | C29: =IF(OR(TRIM(D29)="",COUNTIF(ВидыНагр,F29)<>1),"0",CONCATENATE("$",TRIM(D29),"$",TRIM(E29),"$",F29,"$")) | G29: план | X29: =SUM(J29:W29) | Y29: =X30-X29
A30: =-A29 | B30: =B29 | G30: факт | J30: =SUMIF('09'!$D$7:$D$159,$C29,'09'!L$7:L$159)+SUMIF('10'!$D$7:$D$159,$C29,'10'!L$7:L$159)+SUMIF('11'!$D$7:$D$159,$C29,'11'!L$7:L$159)+SUMIF('12'!$D$7:$D$159,$C29,'12'!L$7:L$159)+SUMIF('01'!$D$7:$D$159,$C29,'01'!L$7:L$159) | K30: =SUMIF('09'!$D$7:$D$159,$C29,'09'!M$7:M$159)+SUMIF('10'!$D$7:$D$159,$C29,'10'!M$7:M$159)+SUMIF('11'!$D$7:$D$159,$C29,'11'!M$7:M$159)+SUMIF('12'!$D$7:$D$159,$C29,'12'!M$7:M$159)+SUMIF('01'!$D$7:$D$159,$C29,'01'!M$7:M$159) | L30: =SUMIF('09'!$D$7:$D$159,$C29,'09'!N$7:N$159)+SUMIF('10'!$D$7:$D$159,$C29,'10'!N$7:N$159)+SUMIF('11'!$D$7:$D$159,$C29,'11'!N$7:N$159)+SUMIF('12'!$D$7:$D$159,$C29,'12'!N$7:N$159)+SUMIF('01'!$D$7:$D$159,$C29,'01'!N$7:N$159) | M30: =SUMIF('09'!$D$7:$D$159,$C29,'09'!O$7:O$159)+SUMIF('10'!$D$7:$D$159,$C29,'10'!O$7:O$159)+SUMIF('11'!$D$7:$D$159,$C29,'11'!O$7:O$159)+SUMIF('12'!$D$7:$D$159,$C29,'12'!O$7:O$159)+SUMIF('01'!$D$7:$D$159,$C29,'01'!O$7:O$159) | N30: =SUMIF('09'!$D$7:$D$159,$C29,'09'!P$7:P$159)+SUMIF('10'!$D$7:$D$159,$C29,'10'!P$7:P$159)+SUMIF('11'!$D$7:$D$159,$C29,'11'!P$7:P$159)+SUMIF('12'!$D$7:$D$159,$C29,'12'!P$7:P$159)+SUMIF('01'!$D$7:$D$159,$C29,'01'!P$7:P$159) | O30: =SUMIF('09'!$D$7:$D$159,$C29,'09'!Q$7:Q$159)+SUMIF('10'!$D$7:$D$159,$C29,'10'!Q$7:Q$159)+SUMIF('11'!$D$7:$D$159,$C29,'11'!Q$7:Q$159)+SUMIF('12'!$D$7:$D$159,$C29,'12'!Q$7:Q$159)+SUMIF('01'!$D$7:$D$159,$C29,'01'!Q$7:Q$159) | P30: =SUMIF('09'!$D$7:$D$159,$C29,'09'!R$7:R$159)+SUMIF('10'!$D$7:$D$159,$C29,'10'!R$7:R$159)+SUMIF('11'!$D$7:$D$159,$C29,'11'!R$7:R$159)+SUMIF('12'!$D$7:$D$159,$C29,'12'!R$7:R$159)+SUMIF('01'!$D$7:$D$159,$C29,'01'!R$7:R$159) | Q30: =SUMIF('09'!$D$7:$D$159,$C29,'09'!S$7:S$159)+SUMIF('10'!$D$7:$D$159,$C29,'10'!S$7:S$159)+SUMIF('11'!$D$7:$D$159,$C29,'11'!S$7:S$159)+SUMIF('12'!$D$7:$D$159,$C29,'12'!S$7:S$159)+SUMIF('01'!$D$7:$D$159,$C29,'01'!S$7:S$159) | ... W30: =SUMIF('09'!$D$7:$D$159,$C29,'09'!Y$7:Y$159)+SUMIF('10'!$D$7:$D$159,$C29,'10'!Y$7:Y$159)+SUMIF('11'!$D$7:$D$159,$C29,'11'!Y$7:Y$159)+SUMIF('12'!$D$7:$D$159,$C29,'12'!Y$7:Y$159)+SUMIF('01'!$D$7:$D$159,$C29,'01'!Y$7:Y$159) | X30: =SUM(J30:W30)
A31: =IF(OR(C31="0",COUNTIF(КлючОсень,C31)>1),0,MATCH(F31,ВидыНагр,0)) | B31: =(COUNTA(D31:F32,J31:W31,H31:I32)=0) | C31: =IF(OR(TRIM(D31)="",COUNTIF(ВидыНагр,F31)<>1),"0",CONCATENATE("$",TRIM(D31),"$",TRIM(E31),"$",F31,"$")) | G31: план | X31: =SUM(J31:W31) | Y31: =X32-X31
A32: =-A31 | B32: =B31 | G32: факт | J32: =SUMIF('09'!$D$7:$D$159,$C31,'09'!L$7:L$159)+SUMIF('10'!$D$7:$D$159,$C31,'10'!L$7:L$159)+SUMIF('11'!$D$7:$D$159,$C31,'11'!L$7:L$159)+SUMIF('12'!$D$7:$D$159,$C31,'12'!L$7:L$159)+SUMIF('01'!$D$7:$D$159,$C31,'01'!L$7:L$159) | K32: =SUMIF('09'!$D$7:$D$159,$C31,'09'!M$7:M$159)+SUMIF('10'!$D$7:$D$159,$C31,'10'!M$7:M$159)+SUMIF('11'!$D$7:$D$159,$C31,'11'!M$7:M$159)+SUMIF('12'!$D$7:$D$159,$C31,'12'!M$7:M$159)+SUMIF('01'!$D$7:$D$159,$C31,'01'!M$7:M$159) | L32: =SUMIF('09'!$D$7:$D$159,$C31,'09'!N$7:N$159)+SUMIF('10'!$D$7:$D$159,$C31,'10'!N$7:N$159)+SUMIF('11'!$D$7:$D$159,$C31,'11'!N$7:N$159)+SUMIF('12'!$D$7:$D$159,$C31,'12'!N$7:N$159)+SUMIF('01'!$D$7:$D$159,$C31,'01'!N$7:N$159) | M32: =SUMIF('09'!$D$7:$D$159,$C31,'09'!O$7:O$159)+SUMIF('10'!$D$7:$D$159,$C31,'10'!O$7:O$159)+SUMIF('11'!$D$7:$D$159,$C31,'11'!O$7:O$159)+SUMIF('12'!$D$7:$D$159,$C31,'12'!O$7:O$159)+SUMIF('01'!$D$7:$D$159,$C31,'01'!O$7:O$159) | N32: =SUMIF('09'!$D$7:$D$159,$C31,'09'!P$7:P$159)+SUMIF('10'!$D$7:$D$159,$C31,'10'!P$7:P$159)+SUMIF('11'!$D$7:$D$159,$C31,'11'!P$7:P$159)+SUMIF('12'!$D$7:$D$159,$C31,'12'!P$7:P$159)+SUMIF('01'!$D$7:$D$159,$C31,'01'!P$7:P$159) | O32: =SUMIF('09'!$D$7:$D$159,$C31,'09'!Q$7:Q$159)+SUMIF('10'!$D$7:$D$159,$C31,'10'!Q$7:Q$159)+SUMIF('11'!$D$7:$D$159,$C31,'11'!Q$7:Q$159)+SUMIF('12'!$D$7:$D$159,$C31,'12'!Q$7:Q$159)+SUMIF('01'!$D$7:$D$159,$C31,'01'!Q$7:Q$159) | P32: =SUMIF('09'!$D$7:$D$159,$C31,'09'!R$7:R$159)+SUMIF('10'!$D$7:$D$159,$C31,'10'!R$7:R$159)+SUMIF('11'!$D$7:$D$159,$C31,'11'!R$7:R$159)+SUMIF('12'!$D$7:$D$159,$C31,'12'!R$7:R$159)+SUMIF('01'!$D$7:$D$159,$C31,'01'!R$7:R$159) | Q32: =SUMIF('09'!$D$7:$D$159,$C31,'09'!S$7:S$159)+SUMIF('10'!$D$7:$D$159,$C31,'10'!S$7:S$159)+SUMIF('11'!$D$7:$D$159,$C31,'11'!S$7:S$159)+SUMIF('12'!$D$7:$D$159,$C31,'12'!S$7:S$159)+SUMIF('01'!$D$7:$D$159,$C31,'01'!S$7:S$159) | ... W32: =SUMIF('09'!$D$7:$D$159,$C31,'09'!Y$7:Y$159)+SUMIF('10'!$D$7:$D$159,$C31,'10'!Y$7:Y$159)+SUMIF('11'!$D$7:$D$159,$C31,'11'!Y$7:Y$159)+SUMIF('12'!$D$7:$D$159,$C31,'12'!Y$7:Y$159)+SUMIF('01'!$D$7:$D$159,$C31,'01'!Y$7:Y$159) | X32: =SUM(J32:W32)
A33: =IF(OR(C33="0",COUNTIF(КлючОсень,C33)>1),0,MATCH(F33,ВидыНагр,0)) | B33: =(COUNTA(D33:F34,J33:W33,H33:I34)=0) | C33: =IF(OR(TRIM(D33)="",COUNTIF(ВидыНагр,F33)<>1),"0",CONCATENATE("$",TRIM(D33),"$",TRIM(E33),"$",F33,"$")) | G33: план | X33: =SUM(J33:W33) | Y33: =X34-X33
A34: =-A33 | B34: =B33 | G34: факт | J34: =SUMIF('09'!$D$7:$D$159,$C33,'09'!L$7:L$159)+SUMIF('10'!$D$7:$D$159,$C33,'10'!L$7:L$159)+SUMIF('11'!$D$7:$D$159,$C33,'11'!L$7:L$159)+SUMIF('12'!$D$7:$D$159,$C33,'12'!L$7:L$159)+SUMIF('01'!$D$7:$D$159,$C33,'01'!L$7:L$159) | K34: =SUMIF('09'!$D$7:$D$159,$C33,'09'!M$7:M$159)+SUMIF('10'!$D$7:$D$159,$C33,'10'!M$7:M$159)+SUMIF('11'!$D$7:$D$159,$C33,'11'!M$7:M$159)+SUMIF('12'!$D$7:$D$159,$C33,'12'!M$7:M$159)+SUMIF('01'!$D$7:$D$159,$C33,'01'!M$7:M$159) | L34: =SUMIF('09'!$D$7:$D$159,$C33,'09'!N$7:N$159)+SUMIF('10'!$D$7:$D$159,$C33,'10'!N$7:N$159)+SUMIF('11'!$D$7:$D$159,$C33,'11'!N$7:N$159)+SUMIF('12'!$D$7:$D$159,$C33,'12'!N$7:N$159)+SUMIF('01'!$D$7:$D$159,$C33,'01'!N$7:N$159) | M34: =SUMIF('09'!$D$7:$D$159,$C33,'09'!O$7:O$159)+SUMIF('10'!$D$7:$D$159,$C33,'10'!O$7:O$159)+SUMIF('11'!$D$7:$D$159,$C33,'11'!O$7:O$159)+SUMIF('12'!$D$7:$D$159,$C33,'12'!O$7:O$159)+SUMIF('01'!$D$7:$D$159,$C33,'01'!O$7:O$159) | N34: =SUMIF('09'!$D$7:$D$159,$C33,'09'!P$7:P$159)+SUMIF('10'!$D$7:$D$159,$C33,'10'!P$7:P$159)+SUMIF('11'!$D$7:$D$159,$C33,'11'!P$7:P$159)+SUMIF('12'!$D$7:$D$159,$C33,'12'!P$7:P$159)+SUMIF('01'!$D$7:$D$159,$C33,'01'!P$7:P$159) | O34: =SUMIF('09'!$D$7:$D$159,$C33,'09'!Q$7:Q$159)+SUMIF('10'!$D$7:$D$159,$C33,'10'!Q$7:Q$159)+SUMIF('11'!$D$7:$D$159,$C33,'11'!Q$7:Q$159)+SUMIF('12'!$D$7:$D$159,$C33,'12'!Q$7:Q$159)+SUMIF('01'!$D$7:$D$159,$C33,'01'!Q$7:Q$159) | P34: =SUMIF('09'!$D$7:$D$159,$C33,'09'!R$7:R$159)+SUMIF('10'!$D$7:$D$159,$C33,'10'!R$7:R$159)+SUMIF('11'!$D$7:$D$159,$C33,'11'!R$7:R$159)+SUMIF('12'!$D$7:$D$159,$C33,'12'!R$7:R$159)+SUMIF('01'!$D$7:$D$159,$C33,'01'!R$7:R$159) | Q34: =SUMIF('09'!$D$7:$D$159,$C33,'09'!S$7:S$159)+SUMIF('10'!$D$7:$D$159,$C33,'10'!S$7:S$159)+SUMIF('11'!$D$7:$D$159,$C33,'11'!S$7:S$159)+SUMIF('12'!$D$7:$D$159,$C33,'12'!S$7:S$159)+SUMIF('01'!$D$7:$D$159,$C33,'01'!S$7:S$159) | ... W34: =SUMIF('09'!$D$7:$D$159,$C33,'09'!Y$7:Y$159)+SUMIF('10'!$D$7:$D$159,$C33,'10'!Y$7:Y$159)+SUMIF('11'!$D$7:$D$159,$C33,'11'!Y$7:Y$159)+SUMIF('12'!$D$7:$D$159,$C33,'12'!Y$7:Y$159)+SUMIF('01'!$D$7:$D$159,$C33,'01'!Y$7:Y$159) | X34: =SUM(J34:W34)
A35: =IF(OR(C35="0",COUNTIF(КлючОсень,C35)>1),0,MATCH(F35,ВидыНагр,0)) | B35: =(COUNTA(D35:F36,J35:W35,H35:I36)=0) | C35: =IF(OR(TRIM(D35)="",COUNTIF(ВидыНагр,F35)<>1),"0",CONCATENATE("$",TRIM(D35),"$",TRIM(E35),"$",F35,"$")) | G35: план | X35: =SUM(J35:W35) | Y35: =X36-X35
